<?xml version="1.0" ?>
<robot name="gpr-20241204">
  <link name="base">
    <inertial>
      <origin rpy="0 0 0" xyz="0 0 0"/>
      <mass value="0.001"/>
      <inertia ixx="0.000001" ixy="0" ixz="0" iyy="0.000001" iyz="0" izz="0.000001"/>
    </inertial>
  </link>
  <joint name="floating_base" type="fixed">
    <origin rpy="0 0 0" xyz="0 0 0"/>
    <parent link="base"/>
    <child link="body1-part"/>
  </joint>
  <link name="body1-part">
    <visual>
      <origin xyz="0 0 0" rpy="0 0 0"/>
      <geometry>
        <mesh filename="meshes/body1-part.stl"/>
      </geometry>
      <material name="body1-part_material">
        <color rgba="0.1 0.1 0.1 1"/>
      </material>
    </visual>
    <collision>
      <origin xyz="0 0 0" rpy="0 0 0"/>
      <geometry>
        <mesh filename="meshes/body1-part.stl"/>
      </geometry>
    </collision>
    <inertial>
      <mass value="11.923537116999999"/>
      <inertia ixx="0.6094741999000399" iyy="0.11402488165934044" izz="0.5176539398431411" ixy="0.005656699650594236" ixz="8.90138051645136e-05" iyz="-0.000151236938435881"/>
      <origin xyz="-0.005366220335650519 -0.1632768315197604 8.549441372027496e-06" rpy="0 0 0"/>
    </inertial>
  </link>
  <joint name="L_shoulder_y" type="revolute">
    <origin xyz="-1.0603759e-05 0.018089562050771318 0.18749980999999996" rpy="3.1415926071795868 -2.220446049250313e-15 3.1415926071795868"/>
    <parent link="body1-part"/>
    <child link="shoulder"/>
    <limit effort="80" velocity="5" lower="0" upper="3.1415927"/>
    <axis xyz="0 0 1"/>
  </joint>
  <link name="shoulder">
    <visual>
      <origin xyz="0 0 0" rpy="0 0 0"/>
      <geometry>
        <mesh filename="meshes/shoulder.stl"/>
      </geometry>
      <material name="shoulder_material">
        <color rgba="0.1 0.1 0.1 1"/>
      </material>
    </visual>
    <collision>
      <origin xyz="0 0 0" rpy="0 0 0"/>
      <geometry>
        <mesh filename="meshes/shoulder.stl"/>
      </geometry>
    </collision>
    <inertial>
      <mass value="1.2849791"/>
      <inertia ixx="0.0017818679340109477" iyy="0.001445520824692282" izz="0.0013710397150226018" ixy="2.4807220509553056e-05" ixz="-2.4268150147392534e-05" iyz="-5.795810527024397e-06"/>
      <origin xyz="-0.007309946302030126 0.0008272272815774785 -0.06707562628946462" rpy="0 0 0"/>
    </inertial>
  </link>
  <joint name="R_shoulder_y" type="revolute">
    <origin xyz="-1.0603759e-05 0.018089564 -0.18750019" rpy="0.0 0.0 -3.1415926071795863"/>
    <parent link="body1-part"/>
    <child link="shoulder_2"/>
    <limit effort="80" velocity="5" lower="-3.1415927" upper="0"/>
    <axis xyz="0 0 1"/>
  </joint>
  <link name="shoulder_2">
    <visual>
      <origin xyz="0 0 0" rpy="0 0 0"/>
      <geometry>
        <mesh filename="meshes/shoulder_2.stl"/>
      </geometry>
      <material name="shoulder_material_2">
        <color rgba="0.1 0.1 0.1 1"/>
      </material>
    </visual>
    <collision>
      <origin xyz="0 0 0" rpy="0 0 0"/>
      <geometry>
        <mesh filename="meshes/shoulder_2.stl"/>
      </geometry>
    </collision>
    <inertial>
      <mass value="0.98497785"/>
      <inertia ixx="0.001479146312102552" iyy="0.0012192357600953635" izz="0.0011445932024187772" ixy="-2.4036370191661273e-05" ixz="-2.469222102498785e-05" iyz="5.667814315970724e-06"/>
      <origin xyz="-0.008087825573652091 -0.0010620417737698827 -0.06694641528073668" rpy="0 0 0"/>
    </inertial>
  </link>
  <joint name="L_shoulder_x" type="revolute">
    <origin xyz="0.022511964 5.627838501275897e-05 -0.06749999993301277" rpy="1.5707963 2.220446049250313e-16 1.5707963"/>
    <parent link="shoulder"/>
    <child link="arm1_top"/>
    <limit effort="80" velocity="5" lower="-0.47996554" upper="3.6302848"/>
    <axis xyz="0 0 -1"/>
  </joint>
  <link name="arm1_top">
    <visual>
      <origin xyz="0 0 0" rpy="0 0 0"/>
      <geometry>
        <mesh filename="meshes/arm1_top.stl"/>
      </geometry>
      <material name="arm1_top_material">
        <color rgba="0.1 0.1 0.1 1"/>
      </material>
    </visual>
    <collision>
      <origin xyz="0 0 0" rpy="0 0 0"/>
      <geometry>
        <mesh filename="meshes/arm1_top.stl"/>
      </geometry>
    </collision>
    <inertial>
      <mass value="1.104715355"/>
      <inertia ixx="0.0014461024725798339" iyy="0.0038527149195150302" izz="0.0037115818412754515" ixy="2.1553326835623183e-05" ixz="-0.000992649530876519" iyz="-2.346162211700897e-05"/>
      <origin xyz="-0.0793711861868692 -0.0012501531488431298 -0.014366141683636266" rpy="0 0 0"/>
    </inertial>
  </link>
  <joint name="R_shoulder_x" type="revolute">
    <origin xyz="0.022511964 -5.627838501275897e-05 -0.06749999993301277" rpy="1.5707963999999996 2.220446049250313e-16 -1.5707963000000003"/>
    <parent link="shoulder_2"/>
    <child link="arm1_top_2"/>
    <limit effort="80" velocity="5" lower="-0.47996554" upper="3.6302848"/>
    <axis xyz="0 0 1"/>
  </joint>
  <link name="arm1_top_2">
    <visual>
      <origin xyz="0 0 0" rpy="0 0 0"/>
      <geometry>
        <mesh filename="meshes/arm1_top_2.stl"/>
      </geometry>
      <material name="arm1_top_2_material">
        <color rgba="0.1 0.1 0.1 1"/>
      </material>
    </visual>
    <collision>
      <origin xyz="0 0 0" rpy="0 0 0"/>
      <geometry>
        <mesh filename="meshes/arm1_top_2.stl"/>
      </geometry>
    </collision>
    <inertial>
      <mass value="1.1047097590000001"/>
      <inertia ixx="0.0014460951154559108" iyy="0.0038527191295710064" izz="0.003711568703919283" ixy="2.155180108243948e-05" ixz="0.0009926450873278694" iyz="2.3462363909827033e-05"/>
      <origin xyz="-0.0793712200786807 -0.0012500837442881883 0.013366232567605326" rpy="0 0 0"/>
    </inertial>
  </link>
  <joint name="L_hip_y" type="revolute">
    <origin xyz="-1.0608503738440467e-05 -0.43201043179234816 0.08770000686486729" rpy="-3.1415925071795874 4.641020723283873e-08 -3.1415926535897913"/>
    <parent link="body1-part"/>
    <child link="leg0_shell"/>
    <limit effort="80" velocity="5" lower="-1.5707963" upper="1.5707963"/>
    <axis xyz="0 0 1"/>
  </joint>
  <link name="leg0_shell">
    <visual>
      <origin xyz="0 0 0" rpy="0 0 0"/>
      <geometry>
        <mesh filename="meshes/leg0_shell.stl"/>
      </geometry>
      <material name="leg0_shell_material">
        <color rgba="0.1 0.1 0.1 1"/>
      </material>
    </visual>
    <collision>
      <origin xyz="0 0 0" rpy="0 0 0"/>
      <geometry>
        <mesh filename="meshes/leg0_shell.stl"/>
      </geometry>
    </collision>
    <inertial>
      <mass value="1.3234480570000002"/>
      <inertia ixx="0.0018858182013085157" iyy="0.0014248321713891826" izz="0.0012997049050806665" ixy="-4.52869566177398e-12" ixz="7.0061936481283574e-06" iyz="-9.656589712159897e-13"/>
      <origin xyz="-0.003746324486178218 -5.307040759284793e-10 -0.06812512159159122" rpy="0 0 0"/>
    </inertial>
  </link>
  <joint name="R_hip_y" type="revolute">
    <origin xyz="-1.0600340183049505e-05 -0.4320104467591277 -0.08819999313513191" rpy="9.99999991702083e-08 4.641020723283873e-08 -3.1415926535897913"/>
    <parent link="body1-part"/>
    <child link="leg0_shell_2"/>
    <limit effort="80" velocity="5" lower="-1.5707963" upper="1.5707963"/>
    <axis xyz="0 0 1"/>
  </joint>
  <link name="leg0_shell_2">
    <visual>
      <origin xyz="0 0 0" rpy="0 0 0"/>
      <geometry>
        <mesh filename="meshes/leg0_shell_2.stl"/>
      </geometry>
      <material name="leg0_shell_material_2">
        <color rgba="0.1 0.1 0.1 1"/>
      </material>
    </visual>
    <collision>
      <origin xyz="0 0 0" rpy="0 0 0"/>
      <geometry>
        <mesh filename="meshes/leg0_shell_2.stl"/>
      </geometry>
    </collision>
    <inertial>
      <mass value="1.3234480570000002"/>
      <inertia ixx="0.0018858182013085157" iyy="0.0014248321713891826" izz="0.0012997049050806665" ixy="-4.52869566177398e-12" ixz="7.0061936481283574e-06" iyz="-9.656589712159897e-13"/>
      <origin xyz="-0.003746324486178218 -5.307040759284793e-10 -0.06812512159159122" rpy="0 0 0"/>
    </inertial>
  </link>
  <joint name="L_shoulder_z" type="revolute">
    <origin xyz="-0.13949999999999996 -1.461921509987972e-09 -0.023499999155960766" rpy="-4.641020604450648e-08 1.5707962732050293 0.0"/>
    <parent link="arm1_top"/>
    <child link="arm2_shell"/>
    <limit effort="80" velocity="5" lower="-1.5707963" upper="1.5707963"/>
    <axis xyz="0 0 1"/>
  </joint>
  <link name="arm2_shell">
    <visual>
      <origin xyz="0 0 0" rpy="0 0 0"/>
      <geometry>
        <mesh filename="meshes/arm2_shell.stl"/>
      </geometry>
      <material name="arm2_shell_material">
        <color rgba="0.1 0.1 0.1 1"/>
      </material>
    </visual>
    <collision>
      <origin xyz="0 0 0" rpy="0 0 0"/>
      <geometry>
        <mesh filename="meshes/arm2_shell.stl"/>
      </geometry>
    </collision>
    <inertial>
      <mass value="0.8887392300000001"/>
      <inertia ixx="0.0018610696979687266" iyy="0.0017324978222628905" izz="0.000872570392026342" ixy="4.4011912397665474e-06" ixz="-5.99604058939538e-05" iyz="5.008762561411801e-05"/>
      <origin xyz="-0.001798710763589256 -0.0011756275753434433 -0.06946281624137632" rpy="0 0 0"/>
    </inertial>
  </link>
  <joint name="R_shoulder_z" type="revolute">
    <origin xyz="-0.13949999999999999 0.0 0.02249999915596076" rpy="-3.1415926071795863 1.5707963 0.0"/>
    <parent link="arm1_top_2"/>
    <child link="arm2_shell_2"/>
    <limit effort="80" velocity="5" lower="-1.5707963" upper="1.5707963"/>
    <axis xyz="0 0 -1"/>
  </joint>
  <link name="arm2_shell_2">
    <visual>
      <origin xyz="0 0 0" rpy="0 0 0"/>
      <geometry>
        <mesh filename="meshes/arm2_shell_2.stl"/>
      </geometry>
      <material name="arm2_shell_material_2">
        <color rgba="0.1 0.1 0.1 1"/>
      </material>
    </visual>
    <collision>
      <origin xyz="0 0 0" rpy="0 0 0"/>
      <geometry>
        <mesh filename="meshes/arm2_shell_2.stl"/>
      </geometry>
    </collision>
    <inertial>
      <mass value="0.88873928"/>
      <inertia ixx="0.00186106971578053" iyy="0.001732497996753827" izz="0.0008725703994993726" ixy="4.401374893970658e-06" ixz="-5.9960230923202884e-05" iyz="5.008759142631026e-05"/>
      <origin xyz="0.001798709333775163 0.0011756251161072753 0.06896280894482125" rpy="0 0 0"/>
    </inertial>
  </link>
  <joint name="L_hip_x" type="revolute">
    <origin xyz="0.026499999999999965 -1.516591136963008e-09 -0.06950000151659115" rpy="-1.5707963 0.0 1.5707963"/>
    <parent link="leg0_shell"/>
    <child link="leg1_shell"/>
    <limit effort="80" velocity="5" lower="-0.34906585" upper="3.1852259"/>
    <axis xyz="0 0 1"/>
  </joint>
  <link name="leg1_shell">
    <visual>
      <origin xyz="0 0 0" rpy="0 0 0"/>
      <geometry>
        <mesh filename="meshes/leg1_shell.stl"/>
      </geometry>
      <material name="leg1_shell_material">
        <color rgba="0.1 0.1 0.1 1"/>
      </material>
    </visual>
    <collision>
      <origin xyz="0 0 0" rpy="0 0 0"/>
      <geometry>
        <mesh filename="meshes/leg1_shell.stl"/>
      </geometry>
    </collision>
    <inertial>
      <mass value="2.3975352720000003"/>
      <inertia ixx="0.00513008818370957" iyy="0.009476500564407108" izz="0.0088231622559438" ixy="0.00016985601645224958" ixz="0.0002920950045878632" iyz="-1.7492434392644974e-05"/>
      <origin xyz="-0.0950080198013173 0.0037889043380580083 0.02610689045557278" rpy="0 0 0"/>
    </inertial>
  </link>
  <joint name="R_hip_x" type="revolute">
    <origin xyz="0.026499999999999965 -1.516591136963008e-09 -0.06950000151659115" rpy="1.5707963 -4.641020678874952e-08 -1.5707963535897917"/>
    <parent link="leg0_shell_2"/>
    <child link="leg1_shell3"/>
    <limit effort="80" velocity="5" lower="-0.34906585" upper="3.1852259"/>
    <axis xyz="0 0 1"/>
  </joint>
  <link name="leg1_shell3">
    <visual>
      <origin xyz="0 0 0" rpy="0 0 0"/>
      <geometry>
        <mesh filename="meshes/leg1_shell3.stl"/>
      </geometry>
      <material name="leg1_shell3_material">
        <color rgba="0.1 0.1 0.1 1"/>
      </material>
    </visual>
    <collision>
      <origin xyz="0 0 0" rpy="0 0 0"/>
      <geometry>
        <mesh filename="meshes/leg1_shell3.stl"/>
      </geometry>
    </collision>
    <inertial>
      <mass value="2.3975351220000003"/>
      <inertia ixx="0.005130088158934349" iyy="0.00944161485874907" izz="0.008788276477099743" ixy="-0.00016144660654649807" ixz="0.0002917611873812629" iyz="1.749256536120334e-05"/>
      <origin xyz="-0.09490783507916396 -0.0037889044403362038 0.02610688434024983" rpy="0 0 0"/>
    </inertial>
  </link>
  <joint name="L_elbow" type="revolute">
    <origin xyz="-0.026 0.0 -0.09799999977224338" rpy="-3.1415926071795863 -1.5707963 0.0"/>
    <parent link="arm2_shell"/>
    <child link="arm3_shell"/>
    <limit effort="80" velocity="5" lower="-2.5307274" upper="0"/>
    <axis xyz="0 0 1"/>
  </joint>
  <link name="arm3_shell">
    <visual>
      <origin xyz="0 0 0" rpy="0 0 0"/>
      <geometry>
        <mesh filename="meshes/arm3_shell.stl"/>
      </geometry>
      <material name="arm3_shell_material">
        <color rgba="0.1 0.1 0.1 1"/>
      </material>
    </visual>
    <collision>
      <origin xyz="0 0 0" rpy="0 0 0"/>
      <geometry>
        <mesh filename="meshes/arm3_shell.stl"/>
      </geometry>
    </collision>
    <inertial>
      <mass value="1.17434502"/>
      <inertia ixx="0.0012948801051846873" iyy="0.00386553769972654" izz="0.0038893141565412583" ixy="-4.145511238363526e-08" ixz="0.00033907822649336923" iyz="-6.773026944302603e-08"/>
      <origin xyz="-0.11165813201227003 2.0198292205436167e-06 0.017954460025568393" rpy="0 0 0"/>
    </inertial>
  </link>
  <joint name="R_elbow" type="revolute">
    <origin xyz="0.026 0.0 0.09750000022775662" rpy="-3.1415926071795863 1.5707963 0.0"/>
    <parent link="arm2_shell_2"/>
    <child link="arm3_shell2"/>
    <limit effort="80" velocity="5" lower="0" upper="2.5307274"/>
    <axis xyz="0 0 1"/>
  </joint>
  <link name="arm3_shell2">
    <visual>
      <origin xyz="0 0 0" rpy="0 0 0"/>
      <geometry>
        <mesh filename="meshes/arm3_shell2.stl"/>
      </geometry>
      <material name="arm3_shell2_material">
        <color rgba="0.1 0.1 0.1 1"/>
      </material>
    </visual>
    <collision>
      <origin xyz="0 0 0" rpy="0 0 0"/>
      <geometry>
        <mesh filename="meshes/arm3_shell2.stl"/>
      </geometry>
    </collision>
    <inertial>
      <mass value="1.17434689"/>
      <inertia ixx="0.0012948841221555808" iyy="0.003865548180886144" izz="0.0038893186559776074" ixy="3.902905046480931e-08" ixz="0.00033907169142936746" iyz="6.378874526651527e-08"/>
      <origin xyz="-0.11165804316148656 -1.90251933533272e-06 0.017954549321009608" rpy="0 0 0"/>
    </inertial>
  </link>
  <joint name="L_hip_z" type="revolute">
    <origin xyz="-0.15649999999999997 0.00011981393 0.02749999848340886" rpy="-0.0 1.5707963 0.0"/>
    <parent link="leg1_shell"/>
    <child link="leg2_shell"/>
    <limit effort="80" velocity="5" lower="-1.5707963" upper="1.5707963"/>
    <axis xyz="0 0 1"/>
  </joint>
  <link name="leg2_shell">
    <visual>
      <origin xyz="0 0 0" rpy="0 0 0"/>
      <geometry>
        <mesh filename="meshes/leg2_shell.stl"/>
      </geometry>
      <material name="leg2_shell_material">
        <color rgba="0.1 0.1 0.1 1"/>
      </material>
    </visual>
    <collision>
      <origin xyz="0 0 0" rpy="0 0 0"/>
      <geometry>
        <mesh filename="meshes/leg2_shell.stl"/>
      </geometry>
    </collision>
    <inertial>
      <mass value="2.3673054970000003"/>
      <inertia ixx="0.008152281452947836" iyy="0.009398349285771936" izz="0.003770744191000254" ixy="3.2924458333985326e-05" ixz="-0.0002976868803852399" iyz="7.085440531149483e-05"/>
      <origin xyz="0.0014620675560682486 9.402559221868402e-06 -0.11494770937326648" rpy="0 0 0"/>
    </inertial>
  </link>
  <joint name="R_hip_z" type="revolute">
    <origin xyz="-0.15649999999999997 -0.00011981393 0.02749999848340886" rpy="-3.1415926535897922 -1.5707962732050305 0.0"/>
    <parent link="leg1_shell3"/>
    <child link="leg2_shell_2"/>
    <limit effort="80" velocity="5" lower="-1.5707963" upper="1.5707963"/>
    <axis xyz="0 0 1"/>
  </joint>
  <link name="leg2_shell_2">
    <visual>
      <origin xyz="0 0 0" rpy="0 0 0"/>
      <geometry>
        <mesh filename="meshes/leg2_shell_2.stl"/>
      </geometry>
      <material name="leg2_shell_material_2">
        <color rgba="0.1 0.1 0.1 1"/>
      </material>
    </visual>
    <collision>
      <origin xyz="0 0 0" rpy="0 0 0"/>
      <geometry>
        <mesh filename="meshes/leg2_shell_2.stl"/>
      </geometry>
    </collision>
    <inertial>
      <mass value="2.367304667"/>
      <inertia ixx="0.008152272161446802" iyy="0.009398356476182234" izz="0.003770753729755378" ixy="-3.293709969359709e-05" ixz="0.0002976690566959898" iyz="7.0853788630271e-05"/>
      <origin xyz="-0.0014613664304116592 9.411936156638673e-06 -0.1149477471506469" rpy="0 0 0"/>
    </inertial>
  </link>
  <joint name="R_wrist" type="revolute">
    <origin xyz="-0.18149999999999994 -1.461921509987972e-09 0.021500000844039233" rpy="-1.5707963535897926 -2.6794894969484062e-08 -1.5707962803846893"/>
    <parent link="arm3_shell"/>
    <child link="hand_shell"/>
    <limit effort="80" velocity="5" lower="0" upper="6.2831853"/>
    <axis xyz="0 0 1"/>
  </joint>
  <link name="hand_shell">
    <visual>
      <origin xyz="0 0 0" rpy="0 0 0"/>
      <geometry>
        <mesh filename="meshes/hand_shell.stl"/>
      </geometry>
      <material name="hand_shell_material">
        <color rgba="0.1 0.1 0.1 1"/>
      </material>
    </visual>
    <collision>
      <origin xyz="0 0 0" rpy="0 0 0"/>
      <geometry>
        <mesh filename="meshes/hand_shell.stl"/>
      </geometry>
    </collision>
    <inertial>
      <mass value="0.7933517460000001"/>
      <inertia ixx="0.002035289036126633" iyy="0.0028711006179816968" izz="0.001279636245454222" ixy="-5.174363969819452e-07" ixz="-2.321711817641545e-05" iyz="3.5513831423902756e-06"/>
      <origin xyz="0.0007087169571505654 0.00012971021920492218 -0.07462970584649938" rpy="0 0 0"/>
    </inertial>
  </link>
  <joint name="L_wrist" type="revolute">
    <origin xyz="-0.18149999999999994 -1.461921509987972e-09 0.021500000844039233" rpy="-1.5707963535897926 -2.6794894969484062e-08 -1.5707962803846893"/>
    <parent link="arm3_shell2"/>
    <child link="hand_shell_2"/>
    <limit effort="80" velocity="5" lower="0" upper="6.2831853"/>
    <axis xyz="0 0 1"/>
  </joint>
  <link name="hand_shell_2">
    <visual>
      <origin xyz="0 0 0" rpy="0 0 0"/>
      <geometry>
        <mesh filename="meshes/hand_shell_2.stl"/>
      </geometry>
      <material name="hand_shell_material_2">
        <color rgba="0.1 0.1 0.1 1"/>
      </material>
    </visual>
    <collision>
      <origin xyz="0 0 0" rpy="0 0 0"/>
      <geometry>
        <mesh filename="meshes/hand_shell_2.stl"/>
      </geometry>
    </collision>
    <inertial>
      <mass value="0.7933517460000001"/>
      <inertia ixx="0.002035289036126633" iyy="0.0028711006179816968" izz="0.001279636245454222" ixy="-5.174363969819452e-07" ixz="-2.321711817641545e-05" iyz="3.5513831423902756e-06"/>
      <origin xyz="0.0007087169571505654 0.00012971021920492218 -0.07462970584649938" rpy="0 0 0"/>
    </inertial>
  </link>
  <joint name="L_knee" type="revolute">
    <origin xyz="0.0 0.0342 -0.14250000009378214" rpy="1.5707963 0.0 0.0"/>
    <parent link="leg2_shell"/>
    <child link="leg3_shell2"/>
    <limit effort="80" velocity="5" lower="-2.0943951" upper="2.0943951"/>
    <axis xyz="0 0 1"/>
  </joint>
  <link name="leg3_shell2">
    <visual>
      <origin xyz="0 0 0" rpy="0 0 0"/>
      <geometry>
        <mesh filename="meshes/leg3_shell2.stl"/>
      </geometry>
      <material name="leg3_shell2_material">
        <color rgba="0.1 0.1 0.1 1"/>
      </material>
    </visual>
    <collision>
      <origin xyz="0 0 0" rpy="0 0 0"/>
      <geometry>
        <mesh filename="meshes/leg3_shell2.stl"/>
      </geometry>
    </collision>
    <inertial>
      <mass value="1.7593333310000001"/>
      <inertia ixx="0.014634941696503407" iyy="0.0028006667735757237" izz="0.014121250092654483" ixy="0.0001111261812450206" ixz="-2.492806777672784e-05" iyz="0.0004989964943990418"/>
      <origin xyz="0.0006926428669608433 -0.09067243147879801 0.03202651009054304" rpy="0 0 0"/>
    </inertial>
  </link>
  <joint name="R_knee" type="revolute">
    <origin xyz="0.0 0.0342 -0.14250000009378214" rpy="1.5707963 0.0 0.0"/>
    <parent link="leg2_shell_2"/>
    <child link="leg3_shell22"/>
    <limit effort="80" velocity="5" lower="-2.0943951" upper="2.0943951"/>
    <axis xyz="0 0 -1"/>
  </joint>
  <link name="leg3_shell22">
    <visual>
      <origin xyz="0 0 0" rpy="0 0 0"/>
      <geometry>
        <mesh filename="meshes/leg3_shell22.stl"/>
      </geometry>
      <material name="leg3_shell22_material">
        <color rgba="0.1 0.1 0.1 1"/>
      </material>
    </visual>
    <collision>
      <origin xyz="0 0 0" rpy="0 0 0"/>
      <geometry>
        <mesh filename="meshes/leg3_shell22.stl"/>
      </geometry>
    </collision>
    <inertial>
      <mass value="1.7593397609999997"/>
      <inertia ixx="0.014634988213860934" iyy="0.002800673552245383" izz="0.014121295403349221" ixy="-0.00011113385224482458" ixz="2.492933731391753e-05" iyz="0.0004990043670736271"/>
      <origin xyz="-0.000692673773305128 -0.09067272009137546 0.03202658918680428" rpy="0 0 0"/>
    </inertial>
  </link>
  <joint name="R_ankle" type="revolute">
    <origin xyz="1.0767167917674625e-08 -0.29999999865410376 0.027200000000000002" rpy="-3.1415926071795868 0.0 -3.1415926071795868"/>
    <parent link="leg3_shell22"/>
    <child link="foot3"/>
    <limit effort="80" velocity="5" lower="-0.6981317" upper="0.6981317"/>
    <axis xyz="0 0 -1"/>
  </joint>
  <link name="foot3">
    <visual>
      <origin xyz="0 0 0" rpy="0 0 0"/>
      <geometry>
        <mesh filename="meshes/foot3.stl"/>
      </geometry>
      <material name="foot3_material">
        <color rgba="0.1 0.1 0.1 1"/>
      </material>
    </visual>
    <collision>
      <origin xyz="0 0 0" rpy="0 0 0"/>
      <geometry>
        <mesh filename="meshes/foot3.stl"/>
      </geometry>
    </collision>
    <inertial>
      <mass value="0.5457471700000001"/>
      <inertia ixx="0.00026065523975398483" iyy="0.0020289390726584825" izz="0.0018716018719932023" ixy="3.696933872469263e-05" ixz="3.095371968865274e-05" iyz="-3.6446932298433347e-06"/>
      <origin xyz="0.021026422150638727 -0.018472025092617035 -0.023695689532891605" rpy="0 0 0"/>
    </inertial>
  </link>
  <joint name="L_ankle" type="revolute">
    <origin xyz="0.0 -0.30000000004641003 0.07019999118206069" rpy="9.282041357749903e-08 0.0 0.0"/>
    <parent link="leg3_shell2"/>
    <child link="foot1"/>
    <limit effort="80" velocity="5" lower="-0.6981317" upper="0.6981317"/>
    <axis xyz="0 0 -1"/>
  </joint>
  <link name="foot1">
    <visual>
      <origin xyz="0 0 0" rpy="0 0 0"/>
      <geometry>
        <mesh filename="meshes/foot1.stl"/>
      </geometry>
      <material name="foot1_material">
        <color rgba="0.1 0.1 0.1 1"/>
      </material>
    </visual>
    <collision>
      <origin xyz="0 0 0" rpy="0 0 0"/>
      <geometry>
        <mesh filename="meshes/foot1.stl"/>
      </geometry>
    </collision>
    <inertial>
      <mass value="0.54574734"/>
      <inertia ixx="0.00026065523992286406" iyy="0.0020289393205482377" izz="0.0018716021578520194" ixy="3.696944831750269e-05" ixz="-3.095376367976456e-05" iyz="3.644697619567395e-06"/>
      <origin xyz="0.021026404502789257 -0.018472020400304597 -0.01930430937248649" rpy="0 0 0"/>
    </inertial>
  </link>
</robot>
