<?xml version="1.0" ?>
<robot name="gpr-20241204">
  <link name="base">
    <inertial>
      <origin rpy="0 0 0" xyz="0 0 0"/>
      <mass value="0.001"/>
      <inertia ixx="0.000001" ixy="0" ixz="0" iyy="0.000001" iyz="0" izz="0.000001"/>
    </inertial>
  </link>
  <joint name="floating_base" type="fixed">
    <origin rpy="0 0 0" xyz="0 0 0"/>
    <parent link="base"/>
    <child link="body1-part"/>
  </joint>
  <link name="body1-part">
    <visual>
      <origin xyz="0 0 0" rpy="0 0 0"/>
      <geometry>
        <mesh filename="meshes/body1-part.stl"/>
      </geometry>
      <material name="body1-part_material">
        <color rgba="1 1 1 1"/>
      </material>
    </visual>
    <collision>
      <origin xyz="0 0 0" rpy="0 0 0"/>
      <geometry>
        <mesh filename="meshes/body1-part.stl"/>
      </geometry>
    </collision>
    <inertial>
      <mass value="1.2310126"/>
      <inertia ixx="0.027487958" iyy="0.021833906" izz="0.0076034713" ixy="-1.9582105e-05" ixz="0" iyz="0"/>
      <origin xyz="0 0 0" rpy="0 0 0"/>
    </inertial>
  </link>
  <joint name="Fastened_16" type="fixed">
    <origin xyz="-1.0603759e-05 0.018089564 0.14549981" rpy="3.1415927 0 0"/>
    <parent link="body1-part"/>
    <child link="body1-part_2"/>
  </joint>
  <link name="body1-part_2">
    <visual>
      <origin xyz="0 0 0" rpy="0 0 0"/>
      <geometry>
        <mesh filename="meshes/body1-part_2.stl"/>
      </geometry>
      <material name="body1-part_material_2">
        <color rgba="1 1 1 1"/>
      </material>
    </visual>
    <collision>
      <origin xyz="0 0 0" rpy="0 0 0"/>
      <geometry>
        <mesh filename="meshes/body1-part_2.stl"/>
      </geometry>
    </collision>
    <inertial>
      <mass value="0.9"/>
      <inertia ixx="0.00067098171" iyy="0.00067098171" izz="0.00090724844" ixy="0" ixz="0" iyz="0"/>
      <origin xyz="0 0 -0.014732068" rpy="0 0 0"/>
    </inertial>
  </link>
  <joint name="Fastened_17" type="fixed">
    <origin xyz="-1.0603759e-05 0.018089564 -0.14550019" rpy="0 0 0"/>
    <parent link="body1-part"/>
    <child link="body1-part_3"/>
  </joint>
  <link name="body1-part_3">
    <visual>
      <origin xyz="0 0 0" rpy="0 0 0"/>
      <geometry>
        <mesh filename="meshes/body1-part_3.stl"/>
      </geometry>
      <material name="body1-part_material_3">
        <color rgba="1 1 1 1"/>
      </material>
    </visual>
    <collision>
      <origin xyz="0 0 0" rpy="0 0 0"/>
      <geometry>
        <mesh filename="meshes/body1-part_3.stl"/>
      </geometry>
    </collision>
    <inertial>
      <mass value="0.9"/>
      <inertia ixx="0.00067098171" iyy="0.00067098171" izz="0.00090724844" ixy="0" ixz="0" iyz="0"/>
      <origin xyz="0 0 -0.014732068" rpy="0 0 0"/>
    </inertial>
  </link>
  <joint name="Fastened_20" type="fixed">
    <origin xyz="-0.024510604 0.092089564 -0.050000186" rpy="-1.5707963 0 -3.1415927"/>
    <parent link="body1-part"/>
    <child link="body1-part_4"/>
  </joint>
  <link name="body1-part_4">
    <visual>
      <origin xyz="0 0 0" rpy="0 0 0"/>
      <geometry>
        <mesh filename="meshes/body1-part_4.stl"/>
      </geometry>
      <material name="body1-part_material_4">
        <color rgba="1 1 1 1"/>
      </material>
    </visual>
    <collision>
      <origin xyz="0 0 0" rpy="0 0 0"/>
      <geometry>
        <mesh filename="meshes/body1-part_4.stl"/>
      </geometry>
    </collision>
    <inertial>
      <mass value="0.58787898"/>
      <inertia ixx="0.0027603188" iyy="0.00086737302" izz="0.0024433121" ixy="3.4344832e-06" ixz="9.8920117e-05" iyz="4.2665282e-06"/>
      <origin xyz="-0.021019429 -0.048755515 -0.038413655" rpy="0 0 0"/>
    </inertial>
  </link>
  <joint name="Fastened_13" type="fixed">
    <origin xyz="0.039989396 0.07830385 -0.15700019" rpy="-1.5707963 0 1.5707963"/>
    <parent link="body1-part"/>
    <child link="back_shell"/>
  </joint>
  <link name="back_shell">
    <visual>
      <origin xyz="0 0 0" rpy="0 0 0"/>
      <geometry>
        <mesh filename="meshes/back_shell.stl"/>
      </geometry>
      <material name="back_shell_material">
        <color rgba="1 1 1 1"/>
      </material>
    </visual>
    <collision>
      <origin xyz="0 0 0" rpy="0 0 0"/>
      <geometry>
        <mesh filename="meshes/back_shell.stl"/>
      </geometry>
    </collision>
    <inertial>
      <mass value="0.24321991"/>
      <inertia ixx="0.0019310343" iyy="0.0011151632" izz="0.0029796264" ixy="0" ixz="2.6407968e-05" iyz="0"/>
      <origin xyz="-0.087802809 -0.15697885 -0.024458018" rpy="0 0 0"/>
    </inertial>
  </link>
  <joint name="Fastened_15" type="fixed">
    <origin xyz="-0.040010604 0.07830385 -0.15700019" rpy="-1.5707963 0 1.5707963"/>
    <parent link="body1-part"/>
    <child link="front_shell"/>
  </joint>
  <link name="front_shell">
    <visual>
      <origin xyz="0 0 0" rpy="0 0 0"/>
      <geometry>
        <mesh filename="meshes/front_shell.stl"/>
      </geometry>
      <material name="front_shell_material">
        <color rgba="1 1 1 1"/>
      </material>
    </visual>
    <collision>
      <origin xyz="0 0 0" rpy="0 0 0"/>
      <geometry>
        <mesh filename="meshes/front_shell.stl"/>
      </geometry>
    </collision>
    <inertial>
      <mass value="0.44765499"/>
      <inertia ixx="0.0034645893" iyy="0.0019394115" izz="0.0052195962" ixy="3.5715688e-05" ixz="-0.0001249107" iyz="8.2800802e-06"/>
      <origin xyz="-0.12203709 -0.15568345 0.030991974" rpy="0 0 0"/>
    </inertial>
  </link>
  <joint name="Fastened_8" type="fixed">
    <origin xyz="-1.0603691e-05 -0.12991044 0" rpy="1.5707963 0 0"/>
    <parent link="body1-part"/>
    <child link="body1-part_5"/>
  </joint>
  <link name="body1-part_5">
    <visual>
      <origin xyz="0 0 0" rpy="0 0 0"/>
      <geometry>
        <mesh filename="meshes/body1-part_5.stl"/>
      </geometry>
      <material name="body1-part_material_5">
        <color rgba="1 1 1 1"/>
      </material>
    </visual>
    <collision>
      <origin xyz="0 0 0" rpy="0 0 0"/>
      <geometry>
        <mesh filename="meshes/body1-part_5.stl"/>
      </geometry>
    </collision>
    <inertial>
      <mass value="0.68030096"/>
      <inertia ixx="0.0086891579" iyy="0.006933761" izz="0.002608882" ixy="8.7755602e-06" ixz="-0.00015085389" iyz="3.1228871e-05"/>
      <origin xyz="-0.0071262559 0.00039370917 0.13888879" rpy="0 0 0"/>
    </inertial>
  </link>
  <joint name="L_shoulder_y" type="revolute">
    <origin xyz="0 0 -0.042" rpy="0 0 3.1415927"/>
    <parent link="body1-part_2"/>
    <child link="shoulder"/>
    <limit effort="80" velocity="5" lower="0" upper="3.1415927"/>
    <axis xyz="0 0 1"/>
  </joint>
  <link name="shoulder">
    <visual>
      <origin xyz="0 0 0" rpy="0 0 0"/>
      <geometry>
        <mesh filename="meshes/shoulder.stl"/>
      </geometry>
      <material name="shoulder_material">
        <color rgba="1 1 1 1"/>
      </material>
    </visual>
    <collision>
      <origin xyz="0 0 0" rpy="0 0 0"/>
      <geometry>
        <mesh filename="meshes/shoulder.stl"/>
      </geometry>
    </collision>
    <inertial>
      <mass value="0.20769407"/>
      <inertia ixx="0.00056970417" iyy="0.00033193722" izz="0.0002822625" ixy="0" ixz="9.8838615e-06" iyz="0"/>
      <origin xyz="0.0091782099 4.9366749e-05 -0.061966361" rpy="0 0 0"/>
    </inertial>
  </link>
  <joint name="Fastened_19" type="fixed">
    <origin xyz="0 0 -0.0395" rpy="0 0 0"/>
    <parent link="body1-part_2"/>
    <child link="body1-part_6"/>
  </joint>
  <link name="body1-part_6">
    <visual>
      <origin xyz="0 0 0" rpy="0 0 0"/>
      <geometry>
        <mesh filename="meshes/body1-part_6.stl"/>
      </geometry>
      <material name="body1-part_material_6">
        <color rgba="1 1 1 1"/>
      </material>
    </visual>
    <collision>
      <origin xyz="0 0 0" rpy="0 0 0"/>
      <geometry>
        <mesh filename="meshes/body1-part_6.stl"/>
      </geometry>
    </collision>
    <inertial>
      <mass value="0.075924533"/>
      <inertia ixx="9.3806565e-06" iyy="4.1635546e-05" izz="4.730836e-05" ixy="0" ixz="0" iyz="0"/>
      <origin xyz="0 -0.03633484 -0.007761698" rpy="0 0 0"/>
    </inertial>
  </link>
  <joint name="R_shoulder_y" type="revolute">
    <origin xyz="0 0 -0.042" rpy="0 0 3.1415927"/>
    <parent link="body1-part_3"/>
    <child link="shoulder_2"/>
    <limit effort="80" velocity="5" lower="-3.1415927" upper="0"/>
    <axis xyz="0 0 1"/>
  </joint>
  <link name="shoulder_2">
    <visual>
      <origin xyz="0 0 0" rpy="0 0 0"/>
      <geometry>
        <mesh filename="meshes/shoulder_2.stl"/>
      </geometry>
      <material name="shoulder_material_2">
        <color rgba="1 1 1 1"/>
      </material>
    </visual>
    <collision>
      <origin xyz="0 0 0" rpy="0 0 0"/>
      <geometry>
        <mesh filename="meshes/shoulder_2.stl"/>
      </geometry>
    </collision>
    <inertial>
      <mass value="0.20769287"/>
      <inertia ixx="0.00056970219" iyy="0.00033193616" izz="0.0002822618" ixy="0" ixz="9.8835172e-06" iyz="0"/>
      <origin xyz="0.0091782992 -4.9389878e-05 -0.061966523" rpy="0 0 0"/>
    </inertial>
  </link>
  <joint name="Fastened_18" type="fixed">
    <origin xyz="0 0 -0.0395" rpy="0 0 0"/>
    <parent link="body1-part_3"/>
    <child link="body1-part_7"/>
  </joint>
  <link name="body1-part_7">
    <visual>
      <origin xyz="0 0 0" rpy="0 0 0"/>
      <geometry>
        <mesh filename="meshes/body1-part_7.stl"/>
      </geometry>
      <material name="body1-part_material_7">
        <color rgba="1 1 1 1"/>
      </material>
    </visual>
    <collision>
      <origin xyz="0 0 0" rpy="0 0 0"/>
      <geometry>
        <mesh filename="meshes/body1-part_7.stl"/>
      </geometry>
    </collision>
    <inertial>
      <mass value="0.075924533"/>
      <inertia ixx="9.3806565e-06" iyy="4.1635546e-05" izz="4.730836e-05" ixy="0" ixz="0" iyz="0"/>
      <origin xyz="0 0.03633484 -0.007761698" rpy="0 0 0"/>
    </inertial>
  </link>
  <joint name="Fastened_21" type="fixed">
    <origin xyz="0.0067 -0.118 -0.0145" rpy="0 1.5707963 0"/>
    <parent link="body1-part_4"/>
    <child link="body1-part_8"/>
  </joint>
  <link name="body1-part_8">
    <visual>
      <origin xyz="0 0 0" rpy="0 0 0"/>
      <geometry>
        <mesh filename="meshes/body1-part_8.stl"/>
      </geometry>
      <material name="body1-part_material_8">
        <color rgba="1 1 1 1"/>
      </material>
    </visual>
    <collision>
      <origin xyz="0 0 0" rpy="0 0 0"/>
      <geometry>
        <mesh filename="meshes/body1-part_8.stl"/>
      </geometry>
    </collision>
    <inertial>
      <mass value="0.021354804"/>
      <inertia ixx="5.3828011e-06" iyy="5.5225944e-06" izz="1.7291974e-06" ixy="0" ixz="0" iyz="0"/>
      <origin xyz="0.0011613298 0 -0.010996315" rpy="0 0 0"/>
    </inertial>
  </link>
  <joint name="Fastened_22" type="fixed">
    <origin xyz="0.0067 0.018 -0.0145" rpy="0 1.5707963 0"/>
    <parent link="body1-part_4"/>
    <child link="body1-part_9"/>
  </joint>
  <link name="body1-part_9">
    <visual>
      <origin xyz="0 0 0" rpy="0 0 0"/>
      <geometry>
        <mesh filename="meshes/body1-part_9.stl"/>
      </geometry>
      <material name="body1-part_material_9">
        <color rgba="1 1 1 1"/>
      </material>
    </visual>
    <collision>
      <origin xyz="0 0 0" rpy="0 0 0"/>
      <geometry>
        <mesh filename="meshes/body1-part_9.stl"/>
      </geometry>
    </collision>
    <inertial>
      <mass value="0.021354804"/>
      <inertia ixx="5.3828011e-06" iyy="5.5225944e-06" izz="1.7291974e-06" ixy="0" ixz="0" iyz="0"/>
      <origin xyz="0.0011613298 0 -0.010996315" rpy="0 0 0"/>
    </inertial>
  </link>
  <joint name="Fastened_23" type="fixed">
    <origin xyz="-0.011681946 -0.05 -0.15525297" rpy="-1.5707963 0 0"/>
    <parent link="body1-part_4"/>
    <child link="body1-part_10"/>
  </joint>
  <link name="body1-part_10">
    <visual>
      <origin xyz="0 0 0" rpy="0 0 0"/>
      <geometry>
        <mesh filename="meshes/body1-part_10.stl"/>
      </geometry>
      <material name="body1-part_material_10">
        <color rgba="1 1 1 1"/>
      </material>
    </visual>
    <collision>
      <origin xyz="0 0 0" rpy="0 0 0"/>
      <geometry>
        <mesh filename="meshes/body1-part_10.stl"/>
      </geometry>
    </collision>
    <inertial>
      <mass value="0.5"/>
      <inertia ixx="0.0017089304" iyy="0.0013256893" izz="0.00042272078" ixy="7.0946166e-05" ixz="0" iyz="0"/>
      <origin xyz="0.011773072 -0.047884504 -2.5681477e-05" rpy="0 0 0"/>
    </inertial>
  </link>
  <joint name="Fastened_25" type="fixed">
    <origin xyz="-0.0096448259 -0.049375 -0.12181656" rpy="-1.5707963 0 0"/>
    <parent link="body1-part_4"/>
    <child link="body1-part_11"/>
  </joint>
  <link name="body1-part_11">
    <visual>
      <origin xyz="0 0 0" rpy="0 0 0"/>
      <geometry>
        <mesh filename="meshes/body1-part_11.stl"/>
      </geometry>
      <material name="body1-part_material_11">
        <color rgba="1 1 1 1"/>
      </material>
    </visual>
    <collision>
      <origin xyz="0 0 0" rpy="0 0 0"/>
      <geometry>
        <mesh filename="meshes/body1-part_11.stl"/>
      </geometry>
    </collision>
    <inertial>
      <mass value="0.046132725"/>
      <inertia ixx="9.9743643e-05" iyy="8.7192252e-05" izz="4.7406393e-05" ixy="-2.0406618e-05" ixz="0" iyz="0"/>
      <origin xyz="-0.03599809 -0.036437089 -1.3840725e-06" rpy="0 0 0"/>
    </inertial>
  </link>
  <joint name="Fastened_1" type="fixed">
    <origin xyz="0.0375 -0.016 0.2911" rpy="3.1415927 0 3.1415927"/>
    <parent link="body1-part_5"/>
    <child link="body1-part_12"/>
  </joint>
  <link name="body1-part_12">
    <visual>
      <origin xyz="0 0 0" rpy="0 0 0"/>
      <geometry>
        <mesh filename="meshes/body1-part_12.stl"/>
      </geometry>
      <material name="body1-part_material_12">
        <color rgba="1 1 1 1"/>
      </material>
    </visual>
    <collision>
      <origin xyz="0 0 0" rpy="0 0 0"/>
      <geometry>
        <mesh filename="meshes/body1-part_12.stl"/>
      </geometry>
    </collision>
    <inertial>
      <mass value="0.55223125"/>
      <inertia ixx="0.0024507681" iyy="0.0015647521" izz="0.0023032522" ixy="0" ixz="0" iyz="0"/>
      <origin xyz="0.037500005 0.01601865 -0.0017942193" rpy="0 0 0"/>
    </inertial>
  </link>
  <joint name="Fastened_9" type="fixed">
    <origin xyz="-0.035 0 0.23695" rpy="1.5707963 0 3.1415927"/>
    <parent link="body1-part_5"/>
    <child link="body1-part_13"/>
  </joint>
  <link name="body1-part_13">
    <visual>
      <origin xyz="0 0 0" rpy="0 0 0"/>
      <geometry>
        <mesh filename="meshes/body1-part_13.stl"/>
      </geometry>
      <material name="body1-part_material_13">
        <color rgba="1 1 1 1"/>
      </material>
    </visual>
    <collision>
      <origin xyz="0 0 0" rpy="0 0 0"/>
      <geometry>
        <mesh filename="meshes/body1-part_13.stl"/>
      </geometry>
    </collision>
    <inertial>
      <mass value="0.2184791"/>
      <inertia ixx="0.0018812453" iyy="0.00053438067" izz="0.0014172355" ixy="-1.3418689e-05" ixz="3.9835645e-06" iyz="2.5774755e-05"/>
      <origin xyz="-0.0088675135 -0.11940575 0.0012061451" rpy="0 0 0"/>
    </inertial>
  </link>
  <joint name="Fastened_10" type="fixed">
    <origin xyz="0.037 -0.0818 0.072175" rpy="0 0 3.1415927"/>
    <parent link="body1-part_5"/>
    <child link="body1-part_14"/>
  </joint>
  <link name="body1-part_14">
    <visual>
      <origin xyz="0 0 0" rpy="0 0 0"/>
      <geometry>
        <mesh filename="meshes/body1-part_14.stl"/>
      </geometry>
      <material name="body1-part_material_14">
        <color rgba="1 1 1 1"/>
      </material>
    </visual>
    <collision>
      <origin xyz="0 0 0" rpy="0 0 0"/>
      <geometry>
        <mesh filename="meshes/body1-part_14.stl"/>
      </geometry>
    </collision>
    <inertial>
      <mass value="0.15852082"/>
      <inertia ixx="0.0010823348" iyy="0.0012376681" izz="0.00017205715" ixy="1.6832432e-06" ixz="-1.9787509e-05" iyz="-7.1180342e-06"/>
      <origin xyz="0.051773802 0.0021228967 0.041474154" rpy="0 0 0"/>
    </inertial>
  </link>
  <joint name="Fastened_2" type="fixed">
    <origin xyz="0.020011964 5.6278452e-05 -0.0675" rpy="1.5707963 0 1.5707963"/>
    <parent link="shoulder"/>
    <child link="shoulder_3"/>
  </joint>
  <link name="shoulder_3">
    <visual>
      <origin xyz="0 0 0" rpy="0 0 0"/>
      <geometry>
        <mesh filename="meshes/shoulder_3.stl"/>
      </geometry>
      <material name="shoulder_material_3">
        <color rgba="1 1 1 1"/>
      </material>
    </visual>
    <collision>
      <origin xyz="0 0 0" rpy="0 0 0"/>
      <geometry>
        <mesh filename="meshes/shoulder_3.stl"/>
      </geometry>
    </collision>
    <inertial>
      <mass value="0.9"/>
      <inertia ixx="0.00067098171" iyy="0.00067098171" izz="0.00090724844" ixy="0" ixz="0" iyz="0"/>
      <origin xyz="0 0 -0.024767932" rpy="0 0 0"/>
    </inertial>
  </link>
  <joint name="Fastened_1_2" type="fixed">
    <origin xyz="0.020011964 -5.6278452e-05 -0.0675" rpy="-1.5707963 0 -1.5707963"/>
    <parent link="shoulder_2"/>
    <child link="shoulder_4"/>
  </joint>
  <link name="shoulder_4">
    <visual>
      <origin xyz="0 0 0" rpy="0 0 0"/>
      <geometry>
        <mesh filename="meshes/shoulder_4.stl"/>
      </geometry>
      <material name="shoulder_material_4">
        <color rgba="1 1 1 1"/>
      </material>
    </visual>
    <collision>
      <origin xyz="0 0 0" rpy="0 0 0"/>
      <geometry>
        <mesh filename="meshes/shoulder_4.stl"/>
      </geometry>
    </collision>
    <inertial>
      <mass value="0.6"/>
      <inertia ixx="0.00044732114" iyy="0.00044732114" izz="0.00060483229" ixy="0" ixz="0" iyz="0"/>
      <origin xyz="0 0 -0.024767932" rpy="0 0 0"/>
    </inertial>
  </link>
  <joint name="Fastened_24" type="fixed">
    <origin xyz="0.026228088 -0.096917942 0" rpy="0 0 0"/>
    <parent link="body1-part_10"/>
    <child link="body1-part_15"/>
  </joint>
  <link name="body1-part_15">
    <visual>
      <origin xyz="0 0 0" rpy="0 0 0"/>
      <geometry>
        <mesh filename="meshes/body1-part_15.stl"/>
      </geometry>
      <material name="body1-part_material_15">
        <color rgba="1 1 1 1"/>
      </material>
    </visual>
    <collision>
      <origin xyz="0 0 0" rpy="0 0 0"/>
      <geometry>
        <mesh filename="meshes/body1-part_15.stl"/>
      </geometry>
    </collision>
    <inertial>
      <mass value="0.13419396"/>
      <inertia ixx="0.00087709138" iyy="0.00060457618" izz="0.00030456603" ixy="5.4188371e-05" ixz="0" iyz="-1.1920801e-05"/>
      <origin xyz="-0.018934315 0.058616542 -0.0057840589" rpy="0 0 0"/>
    </inertial>
  </link>
  <joint name="Fastened_2_2" type="fixed">
    <origin xyz="0.0375 0.0647 -0.011" rpy="-1.5707963 0 0"/>
    <parent link="body1-part_12"/>
    <child link="body1-part_16"/>
  </joint>
  <link name="body1-part_16">
    <visual>
      <origin xyz="0 0 0" rpy="0 0 0"/>
      <geometry>
        <mesh filename="meshes/body1-part_16.stl"/>
      </geometry>
      <material name="body1-part_material_16">
        <color rgba="1 1 1 1"/>
      </material>
    </visual>
    <collision>
      <origin xyz="0 0 0" rpy="0 0 0"/>
      <geometry>
        <mesh filename="meshes/body1-part_16.stl"/>
      </geometry>
    </collision>
    <inertial>
      <mass value="0.9"/>
      <inertia ixx="0.00092667619" iyy="0.00094476194" izz="0.0015093945" ixy="0" ixz="0" iyz="0"/>
      <origin xyz="0 0 0.015265182" rpy="0 0 0"/>
    </inertial>
  </link>
  <joint name="Fastened_3" type="fixed">
    <origin xyz="0.0375 -0.0332 -0.011" rpy="-1.5707963 0 0"/>
    <parent link="body1-part_12"/>
    <child link="body1-part_17"/>
  </joint>
  <link name="body1-part_17">
    <visual>
      <origin xyz="0 0 0" rpy="0 0 0"/>
      <geometry>
        <mesh filename="meshes/body1-part_17.stl"/>
      </geometry>
      <material name="body1-part_material_17">
        <color rgba="1 1 1 1"/>
      </material>
    </visual>
    <collision>
      <origin xyz="0 0 0" rpy="0 0 0"/>
      <geometry>
        <mesh filename="meshes/body1-part_17.stl"/>
      </geometry>
    </collision>
    <inertial>
      <mass value="0.9"/>
      <inertia ixx="0.00092667619" iyy="0.00094476194" izz="0.0015093945" ixy="0" ixz="0" iyz="0"/>
      <origin xyz="0 0 -0.015265182" rpy="0 0 0"/>
    </inertial>
  </link>
  <joint name="Fastened_6" type="fixed">
    <origin xyz="0.001 -0.10185 0" rpy="-1.5707963 0 -1.5707963"/>
    <parent link="body1-part_13"/>
    <child link="body1-part_18"/>
  </joint>
  <link name="body1-part_18">
    <visual>
      <origin xyz="0 0 0" rpy="0 0 0"/>
      <geometry>
        <mesh filename="meshes/body1-part_18.stl"/>
      </geometry>
      <material name="body1-part_material_18">
        <color rgba="1 1 1 1"/>
      </material>
    </visual>
    <collision>
      <origin xyz="0 0 0" rpy="0 0 0"/>
      <geometry>
        <mesh filename="meshes/body1-part_18.stl"/>
      </geometry>
    </collision>
    <inertial>
      <mass value="2.65"/>
      <inertia ixx="0.0045809667" iyy="0.0076119042" izz="0.010495104" ixy="0" ixz="0" iyz="0"/>
      <origin xyz="0 0 -0.031" rpy="0 0 0"/>
    </inertial>
  </link>
  <joint name="Fastened_7" type="fixed">
    <origin xyz="-0.036 -0.165 -0.0725" rpy="-1.5707963 0 -1.5707963"/>
    <parent link="body1-part_13"/>
    <child link="body1-part_19"/>
  </joint>
  <link name="body1-part_19">
    <visual>
      <origin xyz="0 0 0" rpy="0 0 0"/>
      <geometry>
        <mesh filename="meshes/body1-part_19.stl"/>
      </geometry>
      <material name="body1-part_material_19">
        <color rgba="1 1 1 1"/>
      </material>
    </visual>
    <collision>
      <origin xyz="0 0 0" rpy="0 0 0"/>
      <geometry>
        <mesh filename="meshes/body1-part_19.stl"/>
      </geometry>
    </collision>
    <inertial>
      <mass value="0.19664803"/>
      <inertia ixx="0.00048017886" iyy="0.0011617696" izz="0.0016065057" ixy="-2.1892502e-06" ixz="1.2826178e-06" iyz="0"/>
      <origin xyz="-0.049405081 -0.07235961 -0.021136733" rpy="0 0 0"/>
    </inertial>
  </link>
  <joint name="Fastened_12" type="fixed">
    <origin xyz="0.097 -0.0116 0.048" rpy="-1.5707963 0 0"/>
    <parent link="body1-part_14"/>
    <child link="body1-part_20"/>
  </joint>
  <link name="body1-part_20">
    <visual>
      <origin xyz="0 0 0" rpy="0 0 0"/>
      <geometry>
        <mesh filename="meshes/body1-part_20.stl"/>
      </geometry>
      <material name="body1-part_material_20">
        <color rgba="1 1 1 1"/>
      </material>
    </visual>
    <collision>
      <origin xyz="0 0 0" rpy="0 0 0"/>
      <geometry>
        <mesh filename="meshes/body1-part_20.stl"/>
      </geometry>
    </collision>
    <inertial>
      <mass value="0.17091898"/>
      <inertia ixx="0.00094438358" iyy="0.00032664113" izz="0.00063068543" ixy="-3.8619295e-06" ixz="-1.2972089e-06" iyz="-4.0416185e-05"/>
      <origin xyz="0.0023575598 -0.014181111 -0.068512803" rpy="0 0 0"/>
    </inertial>
  </link>
  <joint name="L_shoulder_x" type="revolute">
    <origin xyz="0 0 0.0025" rpy="0 0 0"/>
    <parent link="shoulder_3"/>
    <child link="arm1_top"/>
    <limit effort="80" velocity="5" lower="-0.47996554" upper="3.6302848"/>
    <axis xyz="0 0 -1"/>
  </joint>
  <link name="arm1_top">
    <visual>
      <origin xyz="0 0 0" rpy="0 0 0"/>
      <geometry>
        <mesh filename="meshes/arm1_top.stl"/>
      </geometry>
      <material name="arm1_top_material">
        <color rgba="0.89803922 0.91764706 0.92941176 1"/>
      </material>
    </visual>
    <collision>
      <origin xyz="0 0 0" rpy="0 0 0"/>
      <geometry>
        <mesh filename="meshes/arm1_top.stl"/>
      </geometry>
    </collision>
    <inertial>
      <mass value="0.17273239"/>
      <inertia ixx="0.00014277081" iyy="0.00032836929" izz="0.00031367502" ixy="0" ixz="-7.7657011e-05" iyz="0"/>
      <origin xyz="-0.052942145 -3.8550161e-06 -0.0088528025" rpy="0 0 0"/>
    </inertial>
  </link>
  <joint name="R_shoulder_x" type="revolute">
    <origin xyz="0 0 0.0025" rpy="3.1415927 0 0"/>
    <parent link="shoulder_4"/>
    <child link="arm1_top_2"/>
    <limit effort="80" velocity="5" lower="-0.47996554" upper="3.6302848"/>
    <axis xyz="0 0 1"/>
  </joint>
  <link name="arm1_top_2">
    <visual>
      <origin xyz="0 0 0" rpy="0 0 0"/>
      <geometry>
        <mesh filename="meshes/arm1_top_2.stl"/>
      </geometry>
      <material name="arm1_top_2_material">
        <color rgba="0.89803922 0.91764706 0.92941176 1"/>
      </material>
    </visual>
    <collision>
      <origin xyz="0 0 0" rpy="0 0 0"/>
      <geometry>
        <mesh filename="meshes/arm1_top_2.stl"/>
      </geometry>
    </collision>
    <inertial>
      <mass value="0.17273186"/>
      <inertia ixx="0.00014276994" iyy="0.00032836833" izz="0.00031367483" ixy="0" ixz="7.7656754e-05" iyz="0"/>
      <origin xyz="-0.052942107 -3.5991896e-06 0.0078526534" rpy="0 0 0"/>
    </inertial>
  </link>
  <joint name="L_hip_y" type="revolute">
    <origin xyz="0 0 0.039" rpy="3.1415927 0 0"/>
    <parent link="body1-part_16"/>
    <child link="leg0_shell"/>
    <limit effort="80" velocity="5" lower="-1.5707963" upper="1.5707963"/>
    <axis xyz="0 0 1"/>
  </joint>
  <link name="leg0_shell">
    <visual>
      <origin xyz="0 0 0" rpy="0 0 0"/>
      <geometry>
        <mesh filename="meshes/leg0_shell.stl"/>
      </geometry>
      <material name="leg0_shell_material">
        <color rgba="0.89803922 0.91764706 0.92941176 1"/>
      </material>
    </visual>
    <collision>
      <origin xyz="0 0 0" rpy="0 0 0"/>
      <geometry>
        <mesh filename="meshes/leg0_shell.stl"/>
      </geometry>
    </collision>
    <inertial>
      <mass value="0.37018127"/>
      <inertia ixx="0.00093621354" iyy="0.00065646916" izz="0.00053778412" ixy="0" ixz="2.8249641e-06" iyz="0"/>
      <origin xyz="-0.0060442347 0 -0.064584622" rpy="0 0 0"/>
    </inertial>
  </link>
  <joint name="Fastened_4" type="fixed">
    <origin xyz="0 0 0.039" rpy="3.1415927 0 0"/>
    <parent link="body1-part_16"/>
    <child link="body1-part_21"/>
  </joint>
  <link name="body1-part_21">
    <visual>
      <origin xyz="0 0 0" rpy="0 0 0"/>
      <geometry>
        <mesh filename="meshes/body1-part_21.stl"/>
      </geometry>
      <material name="body1-part_material_21">
        <color rgba="1 1 1 1"/>
      </material>
    </visual>
    <collision>
      <origin xyz="0 0 0" rpy="0 0 0"/>
      <geometry>
        <mesh filename="meshes/body1-part_21.stl"/>
      </geometry>
    </collision>
    <inertial>
      <mass value="0.067658274"/>
      <inertia ixx="3.3775869e-05" iyy="6.8844667e-06" izz="3.7372327e-05" ixy="0" ixz="0" iyz="0"/>
      <origin xyz="-0.043191859 0 -0.0082396077" rpy="0 0 0"/>
    </inertial>
  </link>
  <joint name="R_hip_y" type="revolute">
    <origin xyz="0 0 -0.039" rpy="0 0 0"/>
    <parent link="body1-part_17"/>
    <child link="leg0_shell_2"/>
    <limit effort="80" velocity="5" lower="-1.5707963" upper="1.5707963"/>
    <axis xyz="0 0 1"/>
  </joint>
  <link name="leg0_shell_2">
    <visual>
      <origin xyz="0 0 0" rpy="0 0 0"/>
      <geometry>
        <mesh filename="meshes/leg0_shell_2.stl"/>
      </geometry>
      <material name="leg0_shell_material_2">
        <color rgba="0.89803922 0.91764706 0.92941176 1"/>
      </material>
    </visual>
    <collision>
      <origin xyz="0 0 0" rpy="0 0 0"/>
      <geometry>
        <mesh filename="meshes/leg0_shell_2.stl"/>
      </geometry>
    </collision>
    <inertial>
      <mass value="0.37018127"/>
      <inertia ixx="0.00093621354" iyy="0.00065646916" izz="0.00053778412" ixy="0" ixz="2.8249641e-06" iyz="0"/>
      <origin xyz="-0.0060442347 0 -0.064584622" rpy="0 0 0"/>
    </inertial>
  </link>
  <joint name="Fastened_5" type="fixed">
    <origin xyz="0 0 -0.039" rpy="0 0 0"/>
    <parent link="body1-part_17"/>
    <child link="body1-part_22"/>
  </joint>
  <link name="body1-part_22">
    <visual>
      <origin xyz="0 0 0" rpy="0 0 0"/>
      <geometry>
        <mesh filename="meshes/body1-part_22.stl"/>
      </geometry>
      <material name="body1-part_material_22">
        <color rgba="1 1 1 1"/>
      </material>
    </visual>
    <collision>
      <origin xyz="0 0 0" rpy="0 0 0"/>
      <geometry>
        <mesh filename="meshes/body1-part_22.stl"/>
      </geometry>
    </collision>
    <inertial>
      <mass value="0.067658274"/>
      <inertia ixx="3.3775869e-05" iyy="6.8844667e-06" izz="3.7372327e-05" ixy="0" ixz="0" iyz="0"/>
      <origin xyz="-0.043191859 0 -0.0082396077" rpy="0 0 0"/>
    </inertial>
  </link>
  <joint name="Fastened_11" type="fixed">
    <origin xyz="-1.307028e-05 0.098256596 -0.06658996" rpy="0 0 0"/>
    <parent link="body1-part_20"/>
    <child link="body1-part_23"/>
  </joint>
  <link name="body1-part_23">
    <visual>
      <origin xyz="0 0 0" rpy="0 0 0"/>
      <geometry>
        <mesh filename="meshes/body1-part_23.stl"/>
      </geometry>
      <material name="body1-part_material_23">
        <color rgba="1 1 1 1"/>
      </material>
    </visual>
    <collision>
      <origin xyz="0 0 0" rpy="0 0 0"/>
      <geometry>
        <mesh filename="meshes/body1-part_23.stl"/>
      </geometry>
    </collision>
    <inertial>
      <mass value="0.17646959"/>
      <inertia ixx="0.0012593369" iyy="0.00026382552" izz="0.0014086182" ixy="-5.5379892e-05" ixz="-3.7301337e-05" iyz="-7.234386e-05"/>
      <origin xyz="-0.036013026 -0.081120728 -0.084248178" rpy="0 0 0"/>
    </inertial>
  </link>
  <joint name="Fastened_2_3" type="fixed">
    <origin xyz="-0.108 0 -0.0235" rpy="3.1415927 -1.5707963 0"/>
    <parent link="arm1_top"/>
    <child link="arm-actuator"/>
  </joint>
  <link name="arm-actuator">
    <visual>
      <origin xyz="0 0 0" rpy="0 0 0"/>
      <geometry>
        <mesh filename="meshes/arm-actuator.stl"/>
      </geometry>
      <material name="arm-actuator_material">
        <color rgba="0.79215686 0.81960784 0.93333333 1"/>
      </material>
    </visual>
    <collision>
      <origin xyz="0 0 0" rpy="0 0 0"/>
      <geometry>
        <mesh filename="meshes/arm-actuator.stl"/>
      </geometry>
    </collision>
    <inertial>
      <mass value="0.4"/>
      <inertia ixx="0.00018548163" iyy="0.00018548163" izz="0.00028416296" ixy="0" ixz="0" iyz="0"/>
      <origin xyz="0 0 -0.011585135" rpy="0 0 0"/>
    </inertial>
  </link>
  <joint name="Fastened_1_3" type="fixed">
    <origin xyz="-0.108 0 0.0225" rpy="0 1.5707963 0"/>
    <parent link="arm1_top_2"/>
    <child link="arm-actuator_2"/>
  </joint>
  <link name="arm-actuator_2">
    <visual>
      <origin xyz="0 0 0" rpy="0 0 0"/>
      <geometry>
        <mesh filename="meshes/arm-actuator_2.stl"/>
      </geometry>
      <material name="arm-actuator_material_2">
        <color rgba="0.79215686 0.81960784 0.93333333 1"/>
      </material>
    </visual>
    <collision>
      <origin xyz="0 0 0" rpy="0 0 0"/>
      <geometry>
        <mesh filename="meshes/arm-actuator_2.stl"/>
      </geometry>
    </collision>
    <inertial>
      <mass value="0.4"/>
      <inertia ixx="0.00018548163" iyy="0.00018548163" izz="0.00028416296" ixy="0" ixz="0" iyz="0"/>
      <origin xyz="0 0 -0.011585135" rpy="0 0 0"/>
    </inertial>
  </link>
  <joint name="Fastened_1_4" type="fixed">
    <origin xyz="-0.0301 0 -0.0695" rpy="-1.5707963 0 1.5707963"/>
    <parent link="leg0_shell"/>
    <child link="leg0_actuator"/>
  </joint>
  <link name="leg0_actuator">
    <visual>
      <origin xyz="0 0 0" rpy="0 0 0"/>
      <geometry>
        <mesh filename="meshes/leg0_actuator.stl"/>
      </geometry>
      <material name="leg0_actuator_material">
        <color rgba="0.79215686 0.81960784 0.93333333 1"/>
      </material>
    </visual>
    <collision>
      <origin xyz="0 0 0" rpy="0 0 0"/>
      <geometry>
        <mesh filename="meshes/leg0_actuator.stl"/>
      </geometry>
    </collision>
    <inertial>
      <mass value="0.9"/>
      <inertia ixx="0.00067098171" iyy="0.00067098171" izz="0.00090724844" ixy="0" ixz="0" iyz="0"/>
      <origin xyz="0 0 -0.029332068" rpy="0 0 0"/>
    </inertial>
  </link>
  <joint name="Fastened_2_4" type="fixed">
    <origin xyz="-0.0346 0 -0.0695" rpy="1.5707963 0 1.5707963"/>
    <parent link="leg0_shell"/>
    <child link="leg0_bearing"/>
  </joint>
  <link name="leg0_bearing">
    <visual>
      <origin xyz="0 0 0" rpy="0 0 0"/>
      <geometry>
        <mesh filename="meshes/leg0_bearing.stl"/>
      </geometry>
      <material name="leg0_bearing_material">
        <color rgba="0.89803922 0.91764706 0.92941176 1"/>
      </material>
    </visual>
    <collision>
      <origin xyz="0 0 0" rpy="0 0 0"/>
      <geometry>
        <mesh filename="meshes/leg0_bearing.stl"/>
      </geometry>
    </collision>
    <inertial>
      <mass value="0.053266787"/>
      <inertia ixx="1.8136502e-05" iyy="1.8136502e-05" izz="3.5913995e-05" ixy="0" ixz="0" iyz="0"/>
      <origin xyz="0 0 -0.0035" rpy="0 0 0"/>
    </inertial>
  </link>
  <joint name="Fastened_1_5" type="fixed">
    <origin xyz="-0.0301 0 -0.0695" rpy="-1.5707963 0 1.5707963"/>
    <parent link="leg0_shell_2"/>
    <child link="leg0_actuator_2"/>
  </joint>
  <link name="leg0_actuator_2">
    <visual>
      <origin xyz="0 0 0" rpy="0 0 0"/>
      <geometry>
        <mesh filename="meshes/leg0_actuator_2.stl"/>
      </geometry>
      <material name="leg0_actuator_material_2">
        <color rgba="0.79215686 0.81960784 0.93333333 1"/>
      </material>
    </visual>
    <collision>
      <origin xyz="0 0 0" rpy="0 0 0"/>
      <geometry>
        <mesh filename="meshes/leg0_actuator_2.stl"/>
      </geometry>
    </collision>
    <inertial>
      <mass value="0.9"/>
      <inertia ixx="0.00067098171" iyy="0.00067098171" izz="0.00090724844" ixy="0" ixz="0" iyz="0"/>
      <origin xyz="0 0 -0.029332068" rpy="0 0 0"/>
    </inertial>
  </link>
  <joint name="Fastened_2_5" type="fixed">
    <origin xyz="-0.0346 0 -0.0695" rpy="1.5707963 0 1.5707963"/>
    <parent link="leg0_shell_2"/>
    <child link="leg0_bearing_2"/>
  </joint>
  <link name="leg0_bearing_2">
    <visual>
      <origin xyz="0 0 0" rpy="0 0 0"/>
      <geometry>
        <mesh filename="meshes/leg0_bearing_2.stl"/>
      </geometry>
      <material name="leg0_bearing_material_2">
        <color rgba="0.89803922 0.91764706 0.92941176 1"/>
      </material>
    </visual>
    <collision>
      <origin xyz="0 0 0" rpy="0 0 0"/>
      <geometry>
        <mesh filename="meshes/leg0_bearing_2.stl"/>
      </geometry>
    </collision>
    <inertial>
      <mass value="0.053266787"/>
      <inertia ixx="1.8136502e-05" iyy="1.8136502e-05" izz="3.5913995e-05" ixy="0" ixz="0" iyz="0"/>
      <origin xyz="0 0 -0.0035" rpy="0 0 0"/>
    </inertial>
  </link>
  <joint name="L_shoulder_z" type="revolute">
    <origin xyz="0 0 -0.0315" rpy="0 0 3.1415927"/>
    <parent link="arm-actuator"/>
    <child link="arm2_shell"/>
    <limit effort="80" velocity="5" lower="-1.5707963" upper="1.5707963"/>
    <axis xyz="0 0 1"/>
  </joint>
  <link name="arm2_shell">
    <visual>
      <origin xyz="0 0 0" rpy="0 0 0"/>
      <geometry>
        <mesh filename="meshes/arm2_shell.stl"/>
      </geometry>
      <material name="arm2_shell_material">
        <color rgba="0.89803922 0.91764706 0.92941176 1"/>
      </material>
    </visual>
    <collision>
      <origin xyz="0 0 0" rpy="0 0 0"/>
      <geometry>
        <mesh filename="meshes/arm2_shell.stl"/>
      </geometry>
    </collision>
    <inertial>
      <mass value="0.11101595"/>
      <inertia ixx="0.00028832644" iyy="0.00024383067" izz="6.9077239e-05" ixy="0" ixz="-1.1929973e-05" iyz="0"/>
      <origin xyz="-0.0078489314 0 -0.063113556" rpy="0 0 0"/>
    </inertial>
  </link>
  <joint name="Fastened_4_2" type="fixed">
    <origin xyz="0 0 -0.028" rpy="0 0 -1.5707963"/>
    <parent link="arm-actuator"/>
    <child link="arm-stopper-2.stp"/>
  </joint>
  <link name="arm-stopper-2.stp">
    <visual>
      <origin xyz="0 0 0" rpy="0 0 0"/>
      <geometry>
        <mesh filename="meshes/arm-stopper-2.stp.stl"/>
      </geometry>
      <material name="arm-stopper-2.stp_material">
        <color rgba="1 1 1 1"/>
      </material>
    </visual>
    <collision>
      <origin xyz="0 0 0" rpy="0 0 0"/>
      <geometry>
        <mesh filename="meshes/arm-stopper-2.stp.stl"/>
      </geometry>
    </collision>
    <inertial>
      <mass value="0.075787127"/>
      <inertia ixx="1.0655287e-05" iyy="3.2804007e-05" izz="3.6401092e-05" ixy="0" ixz="0" iyz="-1.7387804e-06"/>
      <origin xyz="-1.0245005e-05 -0.026557758 -0.0099571266" rpy="0 0 0"/>
    </inertial>
  </link>
  <joint name="R_shoulder_z" type="revolute">
    <origin xyz="0 0 -0.0315" rpy="3.1415927 0 0"/>
    <parent link="arm-actuator_2"/>
    <child link="arm2_shell_2"/>
    <limit effort="80" velocity="5" lower="-1.5707963" upper="1.5707963"/>
    <axis xyz="0 0 -1"/>
  </joint>
  <link name="arm2_shell_2">
    <visual>
      <origin xyz="0 0 0" rpy="0 0 0"/>
      <geometry>
        <mesh filename="meshes/arm2_shell_2.stl"/>
      </geometry>
      <material name="arm2_shell_material_2">
        <color rgba="0.89803922 0.91764706 0.92941176 1"/>
      </material>
    </visual>
    <collision>
      <origin xyz="0 0 0" rpy="0 0 0"/>
      <geometry>
        <mesh filename="meshes/arm2_shell_2.stl"/>
      </geometry>
    </collision>
    <inertial>
      <mass value="0.11101595"/>
      <inertia ixx="0.00028832644" iyy="0.00024383067" izz="6.9077239e-05" ixy="0" ixz="-1.1929973e-05" iyz="0"/>
      <origin xyz="0.0078489314 0 0.062613556" rpy="0 0 0"/>
    </inertial>
  </link>
  <joint name="Fastened_3_2" type="fixed">
    <origin xyz="0 0 -0.028" rpy="0 0 1.5707963"/>
    <parent link="arm-actuator_2"/>
    <child link="arm-stopper-2.stp_2"/>
  </joint>
  <link name="arm-stopper-2.stp_2">
    <visual>
      <origin xyz="0 0 0" rpy="0 0 0"/>
      <geometry>
        <mesh filename="meshes/arm-stopper-2.stp_2.stl"/>
      </geometry>
      <material name="arm-stopper-2.stp_material_2">
        <color rgba="1 1 1 1"/>
      </material>
    </visual>
    <collision>
      <origin xyz="0 0 0" rpy="0 0 0"/>
      <geometry>
        <mesh filename="meshes/arm-stopper-2.stp_2.stl"/>
      </geometry>
    </collision>
    <inertial>
      <mass value="0.075787053"/>
      <inertia ixx="1.0655278e-05" iyy="3.2803975e-05" izz="3.6401066e-05" ixy="0" ixz="0" iyz="1.7387821e-06"/>
      <origin xyz="-1.0262515e-05 0.02655776 -0.0099571176" rpy="0 0 0"/>
    </inertial>
  </link>
  <joint name="L_hip_x" type="revolute">
    <origin xyz="0 0 -0.0566" rpy="0 0 0"/>
    <parent link="leg0_actuator"/>
    <child link="leg1_shell"/>
    <limit effort="80" velocity="5" lower="-0.34906585" upper="3.1852259"/>
    <axis xyz="0 0 1"/>
  </joint>
  <link name="leg1_shell">
    <visual>
      <origin xyz="0 0 0" rpy="0 0 0"/>
      <geometry>
        <mesh filename="meshes/leg1_shell.stl"/>
      </geometry>
      <material name="leg1_shell_material">
        <color rgba="0.89803922 0.91764706 0.92941176 1"/>
      </material>
    </visual>
    <collision>
      <origin xyz="0 0 0" rpy="0 0 0"/>
      <geometry>
        <mesh filename="meshes/leg1_shell.stl"/>
      </geometry>
    </collision>
    <inertial>
      <mass value="0.36469032"/>
      <inertia ixx="0.00055741198" iyy="0.00092905072" izz="0.00087158449" ixy="3.3611355e-06" ixz="0.00017329532" iyz="-4.6991851e-06"/>
      <origin xyz="-0.071185176 0.0015379046 0.019705458" rpy="0 0 0"/>
    </inertial>
  </link>
  <joint name="R_hip_x" type="revolute">
    <origin xyz="0 0 -0.0566" rpy="0 0 3.1415927"/>
    <parent link="leg0_actuator_2"/>
    <child link="leg1_shell3"/>
    <limit effort="80" velocity="5" lower="-0.34906585" upper="3.1852259"/>
    <axis xyz="0 0 1"/>
  </joint>
  <link name="leg1_shell3">
    <visual>
      <origin xyz="0 0 0" rpy="0 0 0"/>
      <geometry>
        <mesh filename="meshes/leg1_shell3.stl"/>
      </geometry>
      <material name="leg1_shell3_material">
        <color rgba="0.89803922 0.91764706 0.92941176 1"/>
      </material>
    </visual>
    <collision>
      <origin xyz="0 0 0" rpy="0 0 0"/>
      <geometry>
        <mesh filename="meshes/leg1_shell3.stl"/>
      </geometry>
    </collision>
    <inertial>
      <mass value="0.36469012"/>
      <inertia ixx="0.00055741161" iyy="0.00092905049" izz="0.00087158419" ixy="-3.3613028e-06" ixz="0.00017329523" iyz="4.699312e-06"/>
      <origin xyz="-0.071185167 -0.00153793 0.019705437" rpy="0 0 0"/>
    </inertial>
  </link>
  <joint name="Fastened_1_6" type="fixed">
    <origin xyz="-0.0175 0 -0.098" rpy="0 -1.5707963 0"/>
    <parent link="arm2_shell"/>
    <child link="arm2_actuator"/>
  </joint>
  <link name="arm2_actuator">
    <visual>
      <origin xyz="0 0 0" rpy="0 0 0"/>
      <geometry>
        <mesh filename="meshes/arm2_actuator.stl"/>
      </geometry>
      <material name="arm2_actuator_material">
        <color rgba="0.79215686 0.81960784 0.93333333 1"/>
      </material>
    </visual>
    <collision>
      <origin xyz="0 0 0" rpy="0 0 0"/>
      <geometry>
        <mesh filename="meshes/arm2_actuator.stl"/>
      </geometry>
    </collision>
    <inertial>
      <mass value="0.4"/>
      <inertia ixx="0.00018548163" iyy="0.00018548163" izz="0.00028416296" ixy="0" ixz="0" iyz="0"/>
      <origin xyz="0 0 -0.011585135" rpy="0 0 0"/>
    </inertial>
  </link>
  <joint name="Fastened_1_7" type="fixed">
    <origin xyz="0.0175 0 0.0975" rpy="0 1.5707963 0"/>
    <parent link="arm2_shell_2"/>
    <child link="arm2_actuator_2"/>
  </joint>
  <link name="arm2_actuator_2">
    <visual>
      <origin xyz="0 0 0" rpy="0 0 0"/>
      <geometry>
        <mesh filename="meshes/arm2_actuator_2.stl"/>
      </geometry>
      <material name="arm2_actuator_material_2">
        <color rgba="0.79215686 0.81960784 0.93333333 1"/>
      </material>
    </visual>
    <collision>
      <origin xyz="0 0 0" rpy="0 0 0"/>
      <geometry>
        <mesh filename="meshes/arm2_actuator_2.stl"/>
      </geometry>
    </collision>
    <inertial>
      <mass value="0.4"/>
      <inertia ixx="0.00018548163" iyy="0.00018548163" izz="0.00028416296" ixy="0" ixz="0" iyz="0"/>
      <origin xyz="0 0 -0.011585135" rpy="0 0 0"/>
    </inertial>
  </link>
  <joint name="Fastened_2_6" type="fixed">
    <origin xyz="-0.0999 0.00011981393 0.0275" rpy="0 1.5707963 0"/>
    <parent link="leg1_shell"/>
    <child link="leg1_actuator"/>
  </joint>
  <link name="leg1_actuator">
    <visual>
      <origin xyz="0 0 0" rpy="0 0 0"/>
      <geometry>
        <mesh filename="meshes/leg1_actuator.stl"/>
      </geometry>
      <material name="leg1_actuator_material">
        <color rgba="0.79215686 0.81960784 0.93333333 1"/>
      </material>
    </visual>
    <collision>
      <origin xyz="0 0 0" rpy="0 0 0"/>
      <geometry>
        <mesh filename="meshes/leg1_actuator.stl"/>
      </geometry>
    </collision>
    <inertial>
      <mass value="0.9"/>
      <inertia ixx="0.00067098171" iyy="0.00067098171" izz="0.00090724844" ixy="0" ixz="0" iyz="0"/>
      <origin xyz="0 0 -0.029332068" rpy="0 0 0"/>
    </inertial>
  </link>
  <joint name="Fastened_1_8" type="fixed">
    <origin xyz="-0.0999 -0.00011981393 0.0275" rpy="0 1.5707963 0"/>
    <parent link="leg1_shell3"/>
    <child link="leg1_actuator2"/>
  </joint>
  <link name="leg1_actuator2">
    <visual>
      <origin xyz="0 0 0" rpy="0 0 0"/>
      <geometry>
        <mesh filename="meshes/leg1_actuator2.stl"/>
      </geometry>
      <material name="leg1_actuator2_material">
        <color rgba="0.79215686 0.81960784 0.93333333 1"/>
      </material>
    </visual>
    <collision>
      <origin xyz="0 0 0" rpy="0 0 0"/>
      <geometry>
        <mesh filename="meshes/leg1_actuator2.stl"/>
      </geometry>
    </collision>
    <inertial>
      <mass value="0.9"/>
      <inertia ixx="0.00067098171" iyy="0.00067098171" izz="0.00090724844" ixy="0" ixz="0" iyz="0"/>
      <origin xyz="0 0 -0.029332068" rpy="0 0 0"/>
    </inertial>
  </link>
  <joint name="L_elbow" type="revolute">
    <origin xyz="0 0 0.0085" rpy="3.1415927 0 0"/>
    <parent link="arm2_actuator"/>
    <child link="arm3_shell"/>
    <limit effort="80" velocity="5" lower="0" upper="2.7925268"/>
    <axis xyz="0 0 1"/>
  </joint>
  <link name="arm3_shell">
    <visual>
      <origin xyz="0 0 0" rpy="0 0 0"/>
      <geometry>
        <mesh filename="meshes/arm3_shell.stl"/>
      </geometry>
      <material name="arm3_shell_material">
        <color rgba="0.89803922 0.91764706 0.92941176 1"/>
      </material>
    </visual>
    <collision>
      <origin xyz="0 0 0" rpy="0 0 0"/>
      <geometry>
        <mesh filename="meshes/arm3_shell.stl"/>
      </geometry>
    </collision>
    <inertial>
      <mass value="0.17887479"/>
      <inertia ixx="0.00013849882" iyy="0.00057142188" izz="0.00055471999" ixy="0" ixz="8.7336557e-05" iyz="0"/>
      <origin xyz="-0.092011992 0 0.014776736" rpy="0 0 0"/>
    </inertial>
  </link>
  <joint name="R_elbow" type="revolute">
    <origin xyz="0 0 0.0085" rpy="3.1415927 0 0"/>
    <parent link="arm2_actuator_2"/>
    <child link="arm3_shell2"/>
    <limit effort="80" velocity="5" lower="0" upper="2.7925268"/>
    <axis xyz="0 0 1"/>
  </joint>
  <link name="arm3_shell2">
    <visual>
      <origin xyz="0 0 0" rpy="0 0 0"/>
      <geometry>
        <mesh filename="meshes/arm3_shell2.stl"/>
      </geometry>
      <material name="arm3_shell2_material">
        <color rgba="0.89803922 0.91764706 0.92941176 1"/>
      </material>
    </visual>
    <collision>
      <origin xyz="0 0 0" rpy="0 0 0"/>
      <geometry>
        <mesh filename="meshes/arm3_shell2.stl"/>
      </geometry>
    </collision>
    <inertial>
      <mass value="0.17887479"/>
      <inertia ixx="0.00013849882" iyy="0.00057142188" izz="0.00055471999" ixy="0" ixz="8.7336557e-05" iyz="0"/>
      <origin xyz="-0.092011992 0 0.014776736" rpy="0 0 0"/>
    </inertial>
  </link>
  <joint name="L_hip_z" type="revolute">
    <origin xyz="0 0 -0.0566" rpy="0 0 0"/>
    <parent link="leg1_actuator"/>
    <child link="leg2_shell"/>
    <limit effort="80" velocity="5" lower="-1.5707963" upper="1.5707963"/>
    <axis xyz="0 0 1"/>
  </joint>
  <link name="leg2_shell">
    <visual>
      <origin xyz="0 0 0" rpy="0 0 0"/>
      <geometry>
        <mesh filename="meshes/leg2_shell.stl"/>
      </geometry>
      <material name="leg2_shell_material">
        <color rgba="0.89803922 0.91764706 0.92941176 1"/>
      </material>
    </visual>
    <collision>
      <origin xyz="0 0 0" rpy="0 0 0"/>
      <geometry>
        <mesh filename="meshes/leg2_shell.stl"/>
      </geometry>
    </collision>
    <inertial>
      <mass value="0.26765588"/>
      <inertia ixx="0.0011769735" iyy="0.0013888869" izz="0.00037795879" ixy="0" ixz="0" iyz="5.1336711e-05"/>
      <origin xyz="2.7794893e-06 0.0095055079 -0.10717619" rpy="0 0 0"/>
    </inertial>
  </link>
  <joint name="Fastened_4_3" type="fixed">
    <origin xyz="0 0 -0.0566" rpy="0 0 0"/>
    <parent link="leg1_actuator"/>
    <child link="leg-stopper-2"/>
  </joint>
  <link name="leg-stopper-2">
    <visual>
      <origin xyz="0 0 0" rpy="0 0 0"/>
      <geometry>
        <mesh filename="meshes/leg-stopper-2.stl"/>
      </geometry>
      <material name="leg-stopper-2_material">
        <color rgba="0.89803922 0.91764706 0.92941176 1"/>
      </material>
    </visual>
    <collision>
      <origin xyz="0 0 0" rpy="0 0 0"/>
      <geometry>
        <mesh filename="meshes/leg-stopper-2.stl"/>
      </geometry>
    </collision>
    <inertial>
      <mass value="0.096079192"/>
      <inertia ixx="1.4062902e-05" iyy="4.7759563e-05" izz="4.9482027e-05" ixy="0" ixz="0" iyz="1.28153e-06"/>
      <origin xyz="0 0.038683478 -0.012327581" rpy="0 0 0"/>
    </inertial>
  </link>
  <joint name="R_hip_z" type="revolute">
    <origin xyz="0 0 -0.0566" rpy="0 0 3.1415927"/>
    <parent link="leg1_actuator2"/>
    <child link="leg2_shell_2"/>
    <limit effort="80" velocity="5" lower="-1.5707963" upper="1.5707963"/>
    <axis xyz="0 0 1"/>
  </joint>
  <link name="leg2_shell_2">
    <visual>
      <origin xyz="0 0 0" rpy="0 0 0"/>
      <geometry>
        <mesh filename="meshes/leg2_shell_2.stl"/>
      </geometry>
      <material name="leg2_shell_material_2">
        <color rgba="0.89803922 0.91764706 0.92941176 1"/>
      </material>
    </visual>
    <collision>
      <origin xyz="0 0 0" rpy="0 0 0"/>
      <geometry>
        <mesh filename="meshes/leg2_shell_2.stl"/>
      </geometry>
    </collision>
    <inertial>
      <mass value="0.26765588"/>
      <inertia ixx="0.0011769735" iyy="0.0013888869" izz="0.00037795879" ixy="0" ixz="0" iyz="5.1336711e-05"/>
      <origin xyz="2.7794893e-06 0.0095055079 -0.10717619" rpy="0 0 0"/>
    </inertial>
  </link>
  <joint name="Fastened_3_3" type="fixed">
    <origin xyz="0 0 -0.0541" rpy="0 0 0"/>
    <parent link="leg1_actuator2"/>
    <child link="leg-stopper-2_2"/>
  </joint>
  <link name="leg-stopper-2_2">
    <visual>
      <origin xyz="0 0 0" rpy="0 0 0"/>
      <geometry>
        <mesh filename="meshes/leg-stopper-2_2.stl"/>
      </geometry>
      <material name="leg-stopper-2_material_2">
        <color rgba="0.89803922 0.91764706 0.92941176 1"/>
      </material>
    </visual>
    <collision>
      <origin xyz="0 0 0" rpy="0 0 0"/>
      <geometry>
        <mesh filename="meshes/leg-stopper-2_2.stl"/>
      </geometry>
    </collision>
    <inertial>
      <mass value="0.096079242"/>
      <inertia ixx="1.4062903e-05" iyy="4.7759576e-05" izz="4.9482041e-05" ixy="0" ixz="0" iyz="-1.2815294e-06"/>
      <origin xyz="0 -0.03868348 -0.012327578" rpy="0 0 0"/>
    </inertial>
  </link>
  <joint name="Fastened_2_7" type="fixed">
    <origin xyz="-0.15 0 0.0215" rpy="3.1415927 -1.5707963 0"/>
    <parent link="arm3_shell"/>
    <child link="arm3_actuator"/>
  </joint>
  <link name="arm3_actuator">
    <visual>
      <origin xyz="0 0 0" rpy="0 0 0"/>
      <geometry>
        <mesh filename="meshes/arm3_actuator.stl"/>
      </geometry>
      <material name="arm3_actuator_material">
        <color rgba="0.79215686 0.81960784 0.93333333 1"/>
      </material>
    </visual>
    <collision>
      <origin xyz="0 0 0" rpy="0 0 0"/>
      <geometry>
        <mesh filename="meshes/arm3_actuator.stl"/>
      </geometry>
    </collision>
    <inertial>
      <mass value="0.4"/>
      <inertia ixx="0.00018548163" iyy="0.00018548163" izz="0.00028416296" ixy="0" ixz="0" iyz="0"/>
      <origin xyz="0 0 -0.011585135" rpy="0 0 0"/>
    </inertial>
  </link>
  <joint name="Fastened_1_9" type="fixed">
    <origin xyz="-0.15 0 0.0215" rpy="3.1415927 -1.5707963 0"/>
    <parent link="arm3_shell2"/>
    <child link="arm3_actuator2"/>
  </joint>
  <link name="arm3_actuator2">
    <visual>
      <origin xyz="0 0 0" rpy="0 0 0"/>
      <geometry>
        <mesh filename="meshes/arm3_actuator2.stl"/>
      </geometry>
      <material name="arm3_actuator2_material">
        <color rgba="0.79215686 0.81960784 0.93333333 1"/>
      </material>
    </visual>
    <collision>
      <origin xyz="0 0 0" rpy="0 0 0"/>
      <geometry>
        <mesh filename="meshes/arm3_actuator2.stl"/>
      </geometry>
    </collision>
    <inertial>
      <mass value="0.4"/>
      <inertia ixx="0.00018548163" iyy="0.00018548163" izz="0.00028416296" ixy="0" ixz="0" iyz="0"/>
      <origin xyz="0 0 -0.011585135" rpy="0 0 0"/>
    </inertial>
  </link>
  <joint name="Fastened_1_10" type="fixed">
    <origin xyz="0 0.013 -0.1425" rpy="-1.5707963 0 0"/>
    <parent link="leg2_shell"/>
    <child link="leg2_actuator"/>
  </joint>
  <link name="leg2_actuator">
    <visual>
      <origin xyz="0 0 0" rpy="0 0 0"/>
      <geometry>
        <mesh filename="meshes/leg2_actuator.stl"/>
      </geometry>
      <material name="leg2_actuator_material">
        <color rgba="0.79215686 0.81960784 0.93333333 1"/>
      </material>
    </visual>
    <collision>
      <origin xyz="0 0 0" rpy="0 0 0"/>
      <geometry>
        <mesh filename="meshes/leg2_actuator.stl"/>
      </geometry>
    </collision>
    <inertial>
      <mass value="1.5"/>
      <inertia ixx="0.0015444603" iyy="0.0015746032" izz="0.0025156575" ixy="0" ixz="0" iyz="0"/>
      <origin xyz="0 0 -0.015265182" rpy="0 0 0"/>
    </inertial>
  </link>
  <joint name="Fastened_2_8" type="fixed">
    <origin xyz="0 0.0307 -0.1425" rpy="1.5707963 0 0"/>
    <parent link="leg2_shell"/>
    <child link="leg2_bearing"/>
  </joint>
  <link name="leg2_bearing">
    <visual>
      <origin xyz="0 0 0" rpy="0 0 0"/>
      <geometry>
        <mesh filename="meshes/leg2_bearing.stl"/>
      </geometry>
      <material name="leg2_bearing_material">
        <color rgba="0.79215686 0.81960784 0.93333333 1"/>
      </material>
    </visual>
    <collision>
      <origin xyz="0 0 0" rpy="0 0 0"/>
      <geometry>
        <mesh filename="meshes/leg2_bearing.stl"/>
      </geometry>
    </collision>
    <inertial>
      <mass value="0.053266787"/>
      <inertia ixx="1.8136502e-05" iyy="1.8136502e-05" izz="3.5913995e-05" ixy="0" ixz="0" iyz="0"/>
      <origin xyz="0 0 -0.0035" rpy="0 0 0"/>
    </inertial>
  </link>
  <joint name="Fastened_1_11" type="fixed">
    <origin xyz="0 0.013 -0.1425" rpy="-1.5707963 0 0"/>
    <parent link="leg2_shell_2"/>
    <child link="leg2_actuator_2"/>
  </joint>
  <link name="leg2_actuator_2">
    <visual>
      <origin xyz="0 0 0" rpy="0 0 0"/>
      <geometry>
        <mesh filename="meshes/leg2_actuator_2.stl"/>
      </geometry>
      <material name="leg2_actuator_material_2">
        <color rgba="0.79215686 0.81960784 0.93333333 1"/>
      </material>
    </visual>
    <collision>
      <origin xyz="0 0 0" rpy="0 0 0"/>
      <geometry>
        <mesh filename="meshes/leg2_actuator_2.stl"/>
      </geometry>
    </collision>
    <inertial>
      <mass value="1.5"/>
      <inertia ixx="0.0015444603" iyy="0.0015746032" izz="0.0025156575" ixy="0" ixz="0" iyz="0"/>
      <origin xyz="0 0 -0.015265182" rpy="0 0 0"/>
    </inertial>
  </link>
  <joint name="Fastened_2_9" type="fixed">
    <origin xyz="0 0.0307 -0.1425" rpy="1.5707963 0 0"/>
    <parent link="leg2_shell_2"/>
    <child link="leg2_bearing_2"/>
  </joint>
  <link name="leg2_bearing_2">
    <visual>
      <origin xyz="0 0 0" rpy="0 0 0"/>
      <geometry>
        <mesh filename="meshes/leg2_bearing_2.stl"/>
      </geometry>
      <material name="leg2_bearing_material_2">
        <color rgba="0.79215686 0.81960784 0.93333333 1"/>
      </material>
    </visual>
    <collision>
      <origin xyz="0 0 0" rpy="0 0 0"/>
      <geometry>
        <mesh filename="meshes/leg2_bearing_2.stl"/>
      </geometry>
    </collision>
    <inertial>
      <mass value="0.053266787"/>
      <inertia ixx="1.8136502e-05" iyy="1.8136502e-05" izz="3.5913995e-05" ixy="0" ixz="0" iyz="0"/>
      <origin xyz="0 0 -0.0035" rpy="0 0 0"/>
    </inertial>
  </link>
  <joint name="R_wrist" type="revolute">
    <origin xyz="0 0 -0.0315" rpy="0 0 1.5707963"/>
    <parent link="arm3_actuator"/>
    <child link="hand_shell"/>
    <limit effort="80" velocity="5" lower="0" upper="6.2831853"/>
    <axis xyz="0 0 1"/>
  </joint>
  <link name="hand_shell">
    <visual>
      <origin xyz="0 0 0" rpy="0 0 0"/>
      <geometry>
        <mesh filename="meshes/hand_shell.stl"/>
      </geometry>
      <material name="hand_shell_material">
        <color rgba="0.89803922 0.91764706 0.92941176 1"/>
      </material>
    </visual>
    <collision>
      <origin xyz="0 0 0" rpy="0 0 0"/>
      <geometry>
        <mesh filename="meshes/hand_shell.stl"/>
      </geometry>
    </collision>
    <inertial>
      <mass value="0.27224091"/>
      <inertia ixx="0.00035163322" iyy="0.00081970152" izz="0.00071514974" ixy="0" ixz="-1.9383745e-05" iyz="0"/>
      <origin xyz="0.0020653116 0.00015883163 -0.067811983" rpy="0 0 0"/>
    </inertial>
  </link>
  <joint name="L_wrist" type="revolute">
    <origin xyz="0 0 -0.0315" rpy="0 0 1.5707963"/>
    <parent link="arm3_actuator2"/>
    <child link="hand_shell_2"/>
    <limit effort="80" velocity="5" lower="0" upper="6.2831853"/>
    <axis xyz="0 0 1"/>
  </joint>
  <link name="hand_shell_2">
    <visual>
      <origin xyz="0 0 0" rpy="0 0 0"/>
      <geometry>
        <mesh filename="meshes/hand_shell_2.stl"/>
      </geometry>
      <material name="hand_shell_material_2">
        <color rgba="0.89803922 0.91764706 0.92941176 1"/>
      </material>
    </visual>
    <collision>
      <origin xyz="0 0 0" rpy="0 0 0"/>
      <geometry>
        <mesh filename="meshes/hand_shell_2.stl"/>
      </geometry>
    </collision>
    <inertial>
      <mass value="0.27224091"/>
      <inertia ixx="0.00035163322" iyy="0.00081970152" izz="0.00071514974" ixy="0" ixz="-1.9383745e-05" iyz="0"/>
      <origin xyz="0.0020653116 0.00015883163 -0.067811983" rpy="0 0 0"/>
    </inertial>
  </link>
  <joint name="L_knee" type="revolute">
    <origin xyz="0 0 -0.0035" rpy="0 0 0"/>
    <parent link="leg2_bearing"/>
    <child link="leg3_shell2"/>
    <limit effort="80" velocity="5" lower="-2.0943951" upper="2.0943951"/>
    <axis xyz="0 0 1"/>
  </joint>
  <link name="leg3_shell2">
    <visual>
      <origin xyz="0 0 0" rpy="0 0 0"/>
      <geometry>
        <mesh filename="meshes/leg3_shell2.stl"/>
      </geometry>
      <material name="leg3_shell2_material">
        <color rgba="0.89803922 0.91764706 0.92941176 1"/>
      </material>
    </visual>
    <collision>
      <origin xyz="0 0 0" rpy="0 0 0"/>
      <geometry>
        <mesh filename="meshes/leg3_shell2.stl"/>
      </geometry>
    </collision>
    <inertial>
      <mass value="0.069722151"/>
      <inertia ixx="8.1803983e-05" iyy="4.5383948e-05" izz="0.00011848288" ixy="0" ixz="0" iyz="1.1946282e-05"/>
      <origin xyz="0 -0.03247721 0.006955371" rpy="0 0 0"/>
    </inertial>
  </link>
  <joint name="R_knee" type="revolute">
    <origin xyz="0 0 -0.0035" rpy="0 0 0"/>
    <parent link="leg2_bearing_2"/>
    <child link="leg3_shell22"/>
    <limit effort="80" velocity="5" lower="-2.0943951" upper="2.0943951"/>
    <axis xyz="0 0 -1"/>
  </joint>
  <link name="leg3_shell22">
    <visual>
      <origin xyz="0 0 0" rpy="0 0 0"/>
      <geometry>
        <mesh filename="meshes/leg3_shell22.stl"/>
      </geometry>
      <material name="leg3_shell22_material">
        <color rgba="0.89803922 0.91764706 0.92941176 1"/>
      </material>
    </visual>
    <collision>
      <origin xyz="0 0 0" rpy="0 0 0"/>
      <geometry>
        <mesh filename="meshes/leg3_shell22.stl"/>
      </geometry>
    </collision>
    <inertial>
      <mass value="0.069722381"/>
      <inertia ixx="8.1803971e-05" iyy="4.5384237e-05" izz="0.00011848315" ixy="0" ixz="0" iyz="1.1946209e-05"/>
      <origin xyz="0 -0.032477257 0.0069553217" rpy="0 0 0"/>
    </inertial>
  </link>
  <joint name="Fastened_1_12" type="fixed">
    <origin xyz="0 0 -0.062" rpy="3.1415927 0 0"/>
    <parent link="hand_shell"/>
    <child link="hand_actuator"/>
  </joint>
  <link name="hand_actuator">
    <visual>
      <origin xyz="0 0 0" rpy="0 0 0"/>
      <geometry>
        <mesh filename="meshes/hand_actuator.stl"/>
      </geometry>
      <material name="hand_actuator_material">
        <color rgba="0.79215686 0.81960784 0.93333333 1"/>
      </material>
    </visual>
    <collision>
      <origin xyz="0 0 0" rpy="0 0 0"/>
      <geometry>
        <mesh filename="meshes/hand_actuator.stl"/>
      </geometry>
    </collision>
    <inertial>
      <mass value="0.31"/>
      <inertia ixx="0.00013088778" iyy="0.00013088778" izz="0.00012532318" ixy="0" ixz="0" iyz="0"/>
      <origin xyz="0 0 -0.025309195" rpy="0 0 0"/>
    </inertial>
  </link>
  <joint name="Fastened_2_10" type="fixed">
    <origin xyz="0 -0.029727738 -0.107" rpy="3.1415927 -1.5707963 0"/>
    <parent link="hand_shell"/>
    <child link="hand_shell2"/>
  </joint>
  <link name="hand_shell2">
    <visual>
      <origin xyz="0 0 0" rpy="0 0 0"/>
      <geometry>
        <mesh filename="meshes/hand_shell2.stl"/>
      </geometry>
      <material name="hand_shell2_material">
        <color rgba="0.89803922 0.91764706 0.92941176 1"/>
      </material>
    </visual>
    <collision>
      <origin xyz="0 0 0" rpy="0 0 0"/>
      <geometry>
        <mesh filename="meshes/hand_shell2.stl"/>
      </geometry>
    </collision>
    <inertial>
      <mass value="0.03852471"/>
      <inertia ixx="8.1216505e-05" iyy="6.8941484e-05" izz="1.2300663e-05" ixy="0" ixz="0" iyz="2.3790915e-06"/>
      <origin xyz="-0.00099449627 -0.030012003 0" rpy="0 0 0"/>
    </inertial>
  </link>
  <joint name="Fastened_1_13" type="fixed">
    <origin xyz="0 0 -0.062" rpy="3.1415927 0 0"/>
    <parent link="hand_shell_2"/>
    <child link="hand_actuator_2"/>
  </joint>
  <link name="hand_actuator_2">
    <visual>
      <origin xyz="0 0 0" rpy="0 0 0"/>
      <geometry>
        <mesh filename="meshes/hand_actuator_2.stl"/>
      </geometry>
      <material name="hand_actuator_material_2">
        <color rgba="0.79215686 0.81960784 0.93333333 1"/>
      </material>
    </visual>
    <collision>
      <origin xyz="0 0 0" rpy="0 0 0"/>
      <geometry>
        <mesh filename="meshes/hand_actuator_2.stl"/>
      </geometry>
    </collision>
    <inertial>
      <mass value="0.31"/>
      <inertia ixx="0.00013088778" iyy="0.00013088778" izz="0.00012532318" ixy="0" ixz="0" iyz="0"/>
      <origin xyz="0 0 -0.025309195" rpy="0 0 0"/>
    </inertial>
  </link>
  <joint name="Fastened_2_11" type="fixed">
    <origin xyz="0 -0.029727738 -0.107" rpy="3.1415927 -1.5707963 0"/>
    <parent link="hand_shell_2"/>
    <child link="hand_shell2_2"/>
  </joint>
  <link name="hand_shell2_2">
    <visual>
      <origin xyz="0 0 0" rpy="0 0 0"/>
      <geometry>
        <mesh filename="meshes/hand_shell2_2.stl"/>
      </geometry>
      <material name="hand_shell2_material_2">
        <color rgba="0.89803922 0.91764706 0.92941176 1"/>
      </material>
    </visual>
    <collision>
      <origin xyz="0 0 0" rpy="0 0 0"/>
      <geometry>
        <mesh filename="meshes/hand_shell2_2.stl"/>
      </geometry>
    </collision>
    <inertial>
      <mass value="0.03852471"/>
      <inertia ixx="8.1216505e-05" iyy="6.8941484e-05" izz="1.2300663e-05" ixy="0" ixz="0" iyz="2.3790915e-06"/>
      <origin xyz="-0.00099449627 -0.030012003 0" rpy="0 0 0"/>
    </inertial>
  </link>
  <joint name="Fastened_6_2" type="fixed">
    <origin xyz="0.029 -0.068 0.0222" rpy="0 0 0"/>
    <parent link="leg3_shell2"/>
    <child link="leg3_shell1"/>
  </joint>
  <link name="leg3_shell1">
    <visual>
      <origin xyz="0 0 0" rpy="0 0 0"/>
      <geometry>
        <mesh filename="meshes/leg3_shell1.stl"/>
      </geometry>
      <material name="leg3_shell1_material">
        <color rgba="0.89803922 0.91764706 0.92941176 1"/>
      </material>
    </visual>
    <collision>
      <origin xyz="0 0 0" rpy="0 0 0"/>
      <geometry>
        <mesh filename="meshes/leg3_shell1.stl"/>
      </geometry>
    </collision>
    <inertial>
      <mass value="0.56425494"/>
      <inertia ixx="0.0046192307" iyy="0.00044138531" izz="0.0047994727" ixy="5.3501388e-05" ixz="-5.8832004e-06" iyz="-0.00046247377"/>
      <origin xyz="-0.027048665 -0.059517521 0.023221704" rpy="0 0 0"/>
    </inertial>
  </link>
  <joint name="Fastened_1_14" type="fixed">
    <origin xyz="-0.029 -0.068 0.0222" rpy="0 0 3.1415927"/>
    <parent link="leg3_shell22"/>
    <child link="leg3_shell11"/>
  </joint>
  <link name="leg3_shell11">
    <visual>
      <origin xyz="0 0 0" rpy="0 0 0"/>
      <geometry>
        <mesh filename="meshes/leg3_shell11.stl"/>
      </geometry>
      <material name="leg3_shell11_material">
        <color rgba="0.89803922 0.91764706 0.92941176 1"/>
      </material>
    </visual>
    <collision>
      <origin xyz="0 0 0" rpy="0 0 0"/>
      <geometry>
        <mesh filename="meshes/leg3_shell11.stl"/>
      </geometry>
    </collision>
    <inertial>
      <mass value="0.56426179"/>
      <inertia ixx="0.0046192506" iyy="0.00044138907" izz="0.0047994941" ixy="-5.3508505e-05" ixz="-5.8839789e-06" iyz="0.00046247435"/>
      <origin xyz="-0.027048552 0.059518148 0.023221845" rpy="0 0 0"/>
    </inertial>
  </link>
  <joint name="Fastened_3_4" type="fixed">
    <origin xyz="-0.0010182322 -0.042356503 -0.0545" rpy="3.1415927 0 0"/>
    <parent link="hand_shell2"/>
    <child link="hand_part2"/>
  </joint>
  <link name="hand_part2">
    <visual>
      <origin xyz="0 0 0" rpy="0 0 0"/>
      <geometry>
        <mesh filename="meshes/hand_part2.stl"/>
      </geometry>
      <material name="hand_part2_material">
        <color rgba="0.79215686 0.81960784 0.93333333 1"/>
      </material>
    </visual>
    <collision>
      <origin xyz="0 0 0" rpy="0 0 0"/>
      <geometry>
        <mesh filename="meshes/hand_part2.stl"/>
      </geometry>
    </collision>
    <inertial>
      <mass value="0.022065392"/>
      <inertia ixx="2.8604312e-06" iyy="6.0887761e-06" izz="8.0150705e-06" ixy="-1.5779589e-06" ixz="0" iyz="0"/>
      <origin xyz="-0.021080169 -0.008838172 -0.015263073" rpy="0 0 0"/>
    </inertial>
  </link>
  <joint name="Fastened_5_2" type="fixed">
    <origin xyz="-0.0010182322 -0.017663497 0.0545" rpy="3.1415927 0 0"/>
    <parent link="hand_shell2"/>
    <child link="hand_part"/>
  </joint>
  <link name="hand_part">
    <visual>
      <origin xyz="0 0 0" rpy="0 0 0"/>
      <geometry>
        <mesh filename="meshes/hand_part.stl"/>
      </geometry>
      <material name="hand_part_material">
        <color rgba="0.79215686 0.81960784 0.93333333 1"/>
      </material>
    </visual>
    <collision>
      <origin xyz="0 0 0" rpy="0 0 0"/>
      <geometry>
        <mesh filename="meshes/hand_part.stl"/>
      </geometry>
    </collision>
    <inertial>
      <mass value="0.022065392"/>
      <inertia ixx="2.8604312e-06" iyy="6.0887761e-06" izz="8.0150705e-06" ixy="1.5779589e-06" ixz="0" iyz="0"/>
      <origin xyz="-0.021080169 0.008838172 0.015263073" rpy="0 0 0"/>
    </inertial>
  </link>
  <joint name="Fastened_3_5" type="fixed">
    <origin xyz="-0.0010182322 -0.042356503 -0.0545" rpy="3.1415927 0 0"/>
    <parent link="hand_shell2_2"/>
    <child link="hand_part2_2"/>
  </joint>
  <link name="hand_part2_2">
    <visual>
      <origin xyz="0 0 0" rpy="0 0 0"/>
      <geometry>
        <mesh filename="meshes/hand_part2_2.stl"/>
      </geometry>
      <material name="hand_part2_material_2">
        <color rgba="0.79215686 0.81960784 0.93333333 1"/>
      </material>
    </visual>
    <collision>
      <origin xyz="0 0 0" rpy="0 0 0"/>
      <geometry>
        <mesh filename="meshes/hand_part2_2.stl"/>
      </geometry>
    </collision>
    <inertial>
      <mass value="0.022065392"/>
      <inertia ixx="2.8604312e-06" iyy="6.0887761e-06" izz="8.0150705e-06" ixy="-1.5779589e-06" ixz="0" iyz="0"/>
      <origin xyz="-0.021080169 -0.008838172 -0.015263073" rpy="0 0 0"/>
    </inertial>
  </link>
  <joint name="Fastened_5_3" type="fixed">
    <origin xyz="-0.0010182322 -0.017663497 0.0545" rpy="3.1415927 0 0"/>
    <parent link="hand_shell2_2"/>
    <child link="hand_part_2"/>
  </joint>
  <link name="hand_part_2">
    <visual>
      <origin xyz="0 0 0" rpy="0 0 0"/>
      <geometry>
        <mesh filename="meshes/hand_part_2.stl"/>
      </geometry>
      <material name="hand_part_material_2">
        <color rgba="0.79215686 0.81960784 0.93333333 1"/>
      </material>
    </visual>
    <collision>
      <origin xyz="0 0 0" rpy="0 0 0"/>
      <geometry>
        <mesh filename="meshes/hand_part_2.stl"/>
      </geometry>
    </collision>
    <inertial>
      <mass value="0.022065392"/>
      <inertia ixx="2.8604312e-06" iyy="6.0887761e-06" izz="8.0150705e-06" ixy="1.5779589e-06" ixz="0" iyz="0"/>
      <origin xyz="-0.021080169 0.008838172 0.015263073" rpy="0 0 0"/>
    </inertial>
  </link>
  <joint name="Fastened_3_6" type="fixed">
    <origin xyz="-0.029 -0.042 0.0121" rpy="0 0 0"/>
    <parent link="leg3_shell1"/>
    <child link="leg3_actuator"/>
  </joint>
  <link name="leg3_actuator">
    <visual>
      <origin xyz="0 0 0" rpy="0 0 0"/>
      <geometry>
        <mesh filename="meshes/leg3_actuator.stl"/>
      </geometry>
      <material name="leg3_actuator_material">
        <color rgba="0.79215686 0.81960784 0.93333333 1"/>
      </material>
    </visual>
    <collision>
      <origin xyz="0 0 0" rpy="0 0 0"/>
      <geometry>
        <mesh filename="meshes/leg3_actuator.stl"/>
      </geometry>
    </collision>
    <inertial>
      <mass value="0.4"/>
      <inertia ixx="0.00018548163" iyy="0.00018548163" izz="0.00028416296" ixy="0" ixz="0" iyz="0"/>
      <origin xyz="0 0 -0.016414865" rpy="0 0 0"/>
    </inertial>
  </link>
  <joint name="Fastened_5_4" type="fixed">
    <origin xyz="-0.029 -0.042 0.047" rpy="3.1415927 0 0"/>
    <parent link="leg3_shell1"/>
    <child link="leg3_shell3"/>
  </joint>
  <link name="leg3_shell3">
    <visual>
      <origin xyz="0 0 0" rpy="0 0 0"/>
      <geometry>
        <mesh filename="meshes/leg3_shell3.stl"/>
      </geometry>
      <material name="leg3_shell3_material">
        <color rgba="0.89803922 0.91764706 0.92941176 1"/>
      </material>
    </visual>
    <collision>
      <origin xyz="0 0 0" rpy="0 0 0"/>
      <geometry>
        <mesh filename="meshes/leg3_shell3.stl"/>
      </geometry>
    </collision>
    <inertial>
      <mass value="0.14570047"/>
      <inertia ixx="0.00063417533" iyy="5.6135452e-05" izz="0.00068889977" ixy="-3.6668809e-06" ixz="0" iyz="-6.4804723e-06"/>
      <origin xyz="0.00080671853 0.094588499 0.0006232858" rpy="0 0 0"/>
    </inertial>
  </link>
  <joint name="R_ankle" type="revolute">
    <origin xyz="-0.029 0.232 0.005" rpy="3.1415927 0 0"/>
    <parent link="leg3_shell11"/>
    <child link="foot3"/>
    <limit effort="80" velocity="5" lower="-0.6981317" upper="0.6981317"/>
    <axis xyz="0 0 -1"/>
  </joint>
  <link name="foot3">
    <visual>
      <origin xyz="0 0 0" rpy="0 0 0"/>
      <geometry>
        <mesh filename="meshes/foot3.stl"/>
      </geometry>
      <material name="foot3_material">
        <color rgba="0.89803922 0.91764706 0.92941176 1"/>
      </material>
    </visual>
    <collision>
      <origin xyz="0 0 0" rpy="0 0 0"/>
      <geometry>
        <mesh filename="meshes/foot3.stl"/>
      </geometry>
    </collision>
    <inertial>
      <mass value="0.3129012"/>
      <inertia ixx="0.00015598551" iyy="0.0009939881" izz="0.00089276253" ixy="1.5359534e-05" ixz="1.580541e-05" iyz="-2.6026885e-06"/>
      <origin xyz="0.014045581 -0.013644469 -0.023401374" rpy="0 0 0"/>
    </inertial>
  </link>
  <joint name="Fastened_2_12" type="fixed">
    <origin xyz="-0.029 0.042 0.0121" rpy="0 0 0"/>
    <parent link="leg3_shell11"/>
    <child link="leg3_actuator2"/>
  </joint>
  <link name="leg3_actuator2">
    <visual>
      <origin xyz="0 0 0" rpy="0 0 0"/>
      <geometry>
        <mesh filename="meshes/leg3_actuator2.stl"/>
      </geometry>
      <material name="leg3_actuator2_material">
        <color rgba="0.79215686 0.81960784 0.93333333 1"/>
      </material>
    </visual>
    <collision>
      <origin xyz="0 0 0" rpy="0 0 0"/>
      <geometry>
        <mesh filename="meshes/leg3_actuator2.stl"/>
      </geometry>
    </collision>
    <inertial>
      <mass value="0.4"/>
      <inertia ixx="0.00018548163" iyy="0.00018548163" izz="0.00028416296" ixy="0" ixz="0" iyz="0"/>
      <origin xyz="0 0 -0.016414865" rpy="0 0 0"/>
    </inertial>
  </link>
  <joint name="Fastened_4_4" type="fixed">
    <origin xyz="-0.029 0.042 0.047" rpy="3.1415927 0 0"/>
    <parent link="leg3_shell11"/>
    <child link="leg3_shell33"/>
  </joint>
  <link name="leg3_shell33">
    <visual>
      <origin xyz="0 0 0" rpy="0 0 0"/>
      <geometry>
        <mesh filename="meshes/leg3_shell33.stl"/>
      </geometry>
      <material name="leg3_shell33_material">
        <color rgba="0.89803922 0.91764706 0.92941176 1"/>
      </material>
    </visual>
    <collision>
      <origin xyz="0 0 0" rpy="0 0 0"/>
      <geometry>
        <mesh filename="meshes/leg3_shell33.stl"/>
      </geometry>
    </collision>
    <inertial>
      <mass value="0.14569982"/>
      <inertia ixx="0.00063417464" iyy="5.6135157e-05" izz="0.0006888988" ixy="3.6666303e-06" ixz="0" iyz="6.4804451e-06"/>
      <origin xyz="0.00080661127 -0.094588414 0.00062328876" rpy="0 0 0"/>
    </inertial>
  </link>
  <joint name="Fastened_6_3" type="fixed">
    <origin xyz="-0.05 -0.0125 -0.0125" rpy="3.1415927 0 0"/>
    <parent link="hand_part2"/>
    <child link="hand_umi2"/>
  </joint>
  <link name="hand_umi2">
    <visual>
      <origin xyz="0 0 0" rpy="0 0 0"/>
      <geometry>
        <mesh filename="meshes/hand_umi2.stl"/>
      </geometry>
      <material name="hand_umi2_material">
        <color rgba="0.79215686 0.81960784 0.93333333 1"/>
      </material>
    </visual>
    <collision>
      <origin xyz="0 0 0" rpy="0 0 0"/>
      <geometry>
        <mesh filename="meshes/hand_umi2.stl"/>
      </geometry>
    </collision>
    <inertial>
      <mass value="0.064227671"/>
      <inertia ixx="1.6527818e-05" iyy="6.0431617e-05" izz="6.1915193e-05" ixy="0" ixz="6.1464183e-06" iyz="0"/>
      <origin xyz="0.0061009097 0.00058732212 -0.0021018821" rpy="0 0 0"/>
    </inertial>
  </link>
  <joint name="Fastened_4_5" type="fixed">
    <origin xyz="-0.05 0.0125 0.0125" rpy="0 0 0"/>
    <parent link="hand_part"/>
    <child link="hand_umi"/>
  </joint>
  <link name="hand_umi">
    <visual>
      <origin xyz="0 0 0" rpy="0 0 0"/>
      <geometry>
        <mesh filename="meshes/hand_umi.stl"/>
      </geometry>
      <material name="hand_umi_material">
        <color rgba="0.79215686 0.81960784 0.93333333 1"/>
      </material>
    </visual>
    <collision>
      <origin xyz="0 0 0" rpy="0 0 0"/>
      <geometry>
        <mesh filename="meshes/hand_umi.stl"/>
      </geometry>
    </collision>
    <inertial>
      <mass value="0.064227671"/>
      <inertia ixx="1.6527818e-05" iyy="6.0431617e-05" izz="6.1915193e-05" ixy="0" ixz="6.1464183e-06" iyz="0"/>
      <origin xyz="0.0061009097 0.00058732212 -0.0021018821" rpy="0 0 0"/>
    </inertial>
  </link>
  <joint name="Fastened_6_4" type="fixed">
    <origin xyz="-0.05 -0.0125 -0.0125" rpy="3.1415927 0 0"/>
    <parent link="hand_part2_2"/>
    <child link="hand_umi2_2"/>
  </joint>
  <link name="hand_umi2_2">
    <visual>
      <origin xyz="0 0 0" rpy="0 0 0"/>
      <geometry>
        <mesh filename="meshes/hand_umi2_2.stl"/>
      </geometry>
      <material name="hand_umi2_material_2">
        <color rgba="0.79215686 0.81960784 0.93333333 1"/>
      </material>
    </visual>
    <collision>
      <origin xyz="0 0 0" rpy="0 0 0"/>
      <geometry>
        <mesh filename="meshes/hand_umi2_2.stl"/>
      </geometry>
    </collision>
    <inertial>
      <mass value="0.064227671"/>
      <inertia ixx="1.6527818e-05" iyy="6.0431617e-05" izz="6.1915193e-05" ixy="0" ixz="6.1464183e-06" iyz="0"/>
      <origin xyz="0.0061009097 0.00058732212 -0.0021018821" rpy="0 0 0"/>
    </inertial>
  </link>
  <joint name="Fastened_4_6" type="fixed">
    <origin xyz="-0.05 0.0125 0.0125" rpy="0 0 0"/>
    <parent link="hand_part_2"/>
    <child link="hand_umi_2"/>
  </joint>
  <link name="hand_umi_2">
    <visual>
      <origin xyz="0 0 0" rpy="0 0 0"/>
      <geometry>
        <mesh filename="meshes/hand_umi_2.stl"/>
      </geometry>
      <material name="hand_umi_material_2">
        <color rgba="0.79215686 0.81960784 0.93333333 1"/>
      </material>
    </visual>
    <collision>
      <origin xyz="0 0 0" rpy="0 0 0"/>
      <geometry>
        <mesh filename="meshes/hand_umi_2.stl"/>
      </geometry>
    </collision>
    <inertial>
      <mass value="0.064227671"/>
      <inertia ixx="1.6527818e-05" iyy="6.0431617e-05" izz="6.1915193e-05" ixy="0" ixz="6.1464183e-06" iyz="0"/>
      <origin xyz="0.0061009097 0.00058732212 -0.0021018821" rpy="0 0 0"/>
    </inertial>
  </link>
  <joint name="L_ankle" type="revolute">
    <origin xyz="0 0.19 -0.001" rpy="3.1415927 0 0"/>
    <parent link="leg3_shell3"/>
    <child link="foot1"/>
    <limit effort="80" velocity="5" lower="-0.6981317" upper="0.6981317"/>
    <axis xyz="0 0 -1"/>
  </joint>
  <link name="foot1">
    <visual>
      <origin xyz="0 0 0" rpy="0 0 0"/>
      <geometry>
        <mesh filename="meshes/foot1.stl"/>
      </geometry>
      <material name="foot1_material">
        <color rgba="0.89803922 0.91764706 0.92941176 1"/>
      </material>
    </visual>
    <collision>
      <origin xyz="0 0 0" rpy="0 0 0"/>
      <geometry>
        <mesh filename="meshes/foot1.stl"/>
      </geometry>
    </collision>
    <inertial>
      <mass value="0.31290138"/>
      <inertia ixx="0.0001559855" iyy="0.00099398838" izz="0.00089276282" ixy="1.5359606e-05" ixz="-1.580541e-05" iyz="2.6026876e-06"/>
      <origin xyz="0.014045559 -0.013644464 -0.019598625" rpy="0 0 0"/>
    </inertial>
  </link>
  <joint name="Fastened_1_15" type="fixed">
    <origin xyz="0.11 -0.015 -0.0025" rpy="-1.5707963 0 0"/>
    <parent link="foot3"/>
    <child link="foot4"/>
  </joint>
  <link name="foot4">
    <visual>
      <origin xyz="0 0 0" rpy="0 0 0"/>
      <geometry>
        <mesh filename="meshes/foot4.stl"/>
      </geometry>
      <material name="foot4_material">
        <color rgba="0.79215686 0.81960784 0.93333333 1"/>
      </material>
    </visual>
    <collision>
      <origin xyz="0 0 0" rpy="0 0 0"/>
      <geometry>
        <mesh filename="meshes/foot4.stl"/>
      </geometry>
    </collision>
    <inertial>
      <mass value="0.23284597"/>
      <inertia ixx="8.7514527e-05" iyy="0.00092600841" izz="0.00099914819" ixy="-1.3641526e-05" ixz="-3.105449e-06" iyz="0"/>
      <origin xyz="-0.07959264 0.021591194 -0.0099593533" rpy="0 0 0"/>
    </inertial>
  </link>
  <joint name="Fastened_2_13" type="fixed">
    <origin xyz="0.125 -0.015 0.0015" rpy="-1.5707963 0 0"/>
    <parent link="foot1"/>
    <child link="foot2"/>
  </joint>
  <link name="foot2">
    <visual>
      <origin xyz="0 0 0" rpy="0 0 0"/>
      <geometry>
        <mesh filename="meshes/foot2.stl"/>
      </geometry>
      <material name="foot2_material">
        <color rgba="0.79215686 0.81960784 0.93333333 1"/>
      </material>
    </visual>
    <collision>
      <origin xyz="0 0 0" rpy="0 0 0"/>
      <geometry>
        <mesh filename="meshes/foot2.stl"/>
      </geometry>
    </collision>
    <inertial>
      <mass value="0.23284596"/>
      <inertia ixx="8.7514519e-05" iyy="0.00092600831" izz="0.00099914808" ixy="1.3641567e-05" ixz="-3.1054521e-06" iyz="0"/>
      <origin xyz="-0.094592646 0.020408804 -0.009959353" rpy="0 0 0"/>
    </inertial>
  </link>
</robot>
