<mujoco model="gpr-20241204">
  <option iterations="50" timestep="0.001" solver="PGS" gravity="0 0 -9.81" />

  <compiler angle="radian" meshdir="meshes" eulerseq="zyx" autolimits="true" />

  <default>
    <joint limited="true" damping="0.01" armature="0.01" frictionloss="0.01" />
    <geom condim="4" contype="1" conaffinity="15" friction="0.9 0.2 0.2" solref="0.001 2" />
    <motor ctrllimited="true" />
    <equality solref="0.001 2" />
    <default class="visualgeom">
      <geom material="visualgeom" condim="1" contype="0" conaffinity="0" />
    </default>
  </default>

  <asset>
    <mesh name="body1-part" file="body1-part.stl" />
    <mesh name="shoulder" file="shoulder.stl" />
    <mesh name="shoulder_2" file="shoulder_2.stl" />
    <mesh name="arm1_top" file="arm1_top.stl" />
    <mesh name="arm1_top_2" file="arm1_top_2.stl" />
    <mesh name="leg0_shell" file="leg0_shell.stl" />
    <mesh name="leg0_shell_2" file="leg0_shell_2.stl" />
    <mesh name="arm2_shell" file="arm2_shell.stl" />
    <mesh name="arm2_shell_2" file="arm2_shell_2.stl" />
    <mesh name="leg1_shell" file="leg1_shell.stl" />
    <mesh name="leg1_shell3" file="leg1_shell3.stl" />
    <mesh name="arm3_shell" file="arm3_shell.stl" />
    <mesh name="arm3_shell2" file="arm3_shell2.stl" />
    <mesh name="leg2_shell" file="leg2_shell.stl" />
    <mesh name="leg2_shell_2" file="leg2_shell_2.stl" />
    <mesh name="hand_shell" file="hand_shell.stl" />
    <mesh name="hand_shell_2" file="hand_shell_2.stl" />
    <mesh name="leg3_shell2" file="leg3_shell2.stl" />
    <mesh name="leg3_shell22" file="leg3_shell22.stl" />
    <mesh name="foot3" file="foot3.stl" />
    <mesh name="foot1" file="foot1.stl" />
    <texture name="texplane" type="2d" builtin="checker" rgb1=".0 .0 .0" rgb2=".8 .8 .8" width="100" height="100" />
    <material name="matplane" reflectance="0." texture="texplane" texrepeat="1 1" texuniform="true" />
    <material name="visualgeom" rgba="0.5 0.9 0.2 1" />
  </asset>

  <worldbody>
    <light directional="true" diffuse="0.4 0.4 0.4" specular="0.1 0.1 0.1" pos="0 0 5.0" dir="0 0 -1" castshadow="false" />
    <light directional="true" diffuse="0.6 0.6 0.6" specular="0.2 0.2 0.2" pos="0 0 4" dir="0 0 -1" />
    <geom name="ground" type="plane" pos="0 0 0" size="100 100 0.001" quat="1 0 0 0" material="matplane" condim="3" conaffinity="15" />
    <camera name="fixed" pos="0 -3.0 0.5" xyaxes="1 0 0 0 0 1" />
    <camera name="track" mode="trackcom" pos="0 -3.0 0.5" xyaxes="1 0 0 0 0 1" />
    <body name="root" pos="0 0 0.01" quat="1 0 0 0">
      <freejoint name="root" />
      <site name="imu" size="0.01" pos="0 0 0" />
      <geom type="mesh" rgba="1 1 1 1" mesh="body1-part" contype="1" conaffinity="0" density="0" group="1" class="visualgeom" />
      <geom type="mesh" rgba="1 1 1 1" mesh="body1-part" />
      <body name="shoulder" pos="-1.06038e-05 0.0180896 0.1875" quat="0 2.32051e-08 1 2.32051e-08">
        <inertial pos="-0.00730995 0.000827227 -0.0670756" quat="0.998487 -0.0279049 0.0286765 0.0377207" mass="1.28498" diaginertia="0.00178515 0.00144392 0.00136936" />
        <joint name="L_shoulder_y" pos="0 0 0" axis="0 0 1" range="0 3.14159" actuatorfrcrange="-80 80" />
        <geom type="mesh" rgba="0.121569 0.121569 0.137255 1" mesh="shoulder" contype="1" conaffinity="0" density="0" group="1" class="visualgeom" />
        <geom type="mesh" rgba="0.121569 0.121569 0.137255 1" mesh="shoulder" />
        <body name="arm1_top" pos="0.022512 5.62784e-05 -0.0675" quat="0.5 0.5 0.5 0.5">
          <inertial pos="-0.0793712 -0.00125015 -0.0143661" quat="-0.0499719 0.567978 -0.0371955 0.820683" mass="1.10472" diaginertia="0.00408868 0.00384907 0.00107265" />
          <joint name="L_shoulder_x" pos="0 0 0" axis="0 0 -1" range="-0.479966 3.63028" actuatorfrcrange="-80 80" />
          <geom type="mesh" rgba="0.121569 0.121569 0.137255 1" mesh="arm1_top" contype="1" conaffinity="0" density="0" group="1" class="visualgeom" />
          <geom type="mesh" rgba="0.121569 0.121569 0.137255 1" mesh="arm1_top" />
          <body name="arm2_shell" pos="-0.1395 -1.46192e-09 -0.0235" quat="0.707107 -1.64085e-08 0.707107 1.64085e-08">
            <inertial pos="-0.00179871 -0.00117563 -0.0694628" quat="0.999115 0.0291134 0.0300503 0.00441732" mass="0.888739" diaginertia="0.00186471 0.0017354 0.000866031" />
            <joint name="L_shoulder_z" pos="0 0 0" axis="0 0 1" range="-1.5708 1.5708" actuatorfrcrange="-80 80" />
            <geom type="mesh" rgba="0.121569 0.121569 0.137255 1" mesh="arm2_shell" contype="1" conaffinity="0" density="0" group="1" class="visualgeom" />
            <geom type="mesh" rgba="0.121569 0.121569 0.137255 1" mesh="arm2_shell" />
            <body name="arm3_shell" pos="-0.026 0 -0.098" quat="1.64085e-08 -0.707107 -1.64085e-08 -0.707107">
              <inertial pos="-0.111658 2.01983e-06 0.0179545" quat="-0.000359929 0.750828 -0.000399748 0.660497" mass="1.17435" diaginertia="0.0039329 0.00386554 0.0012513" />
              <joint name="L_elbow" pos="0 0 0" axis="0 0 1" range="-2.53073 0" actuatorfrcrange="-80 80" />
              <geom type="mesh" rgba="0.121569 0.121569 0.137255 1" mesh="arm3_shell" contype="1" conaffinity="0" density="0" group="1" class="visualgeom" />
              <geom type="mesh" rgba="0.121569 0.121569 0.137255 1" mesh="arm3_shell" />
              <body name="hand_shell" pos="-0.1815 -1.46192e-09 0.0215" quat="0.5 -0.5 0.5 -0.5">
                <inertial pos="0.000708717 0.00012971 -0.0746297" quat="0.70677 0.0116364 0.0100591 0.707276" mass="0.793352" diaginertia="0.00287111 0.002036 0.00127892" />
                <joint name="R_wrist" pos="0 0 0" axis="0 0 1" range="0 6.28319" actuatorfrcrange="-80 80" />
                <geom type="mesh" rgba="0.121569 0.121569 0.137255 1" mesh="hand_shell" contype="1" conaffinity="0" density="0" group="1" class="visualgeom" />
                <geom type="mesh" rgba="0.121569 0.121569 0.137255 1" mesh="hand_shell" />
              </body>
            </body>
          </body>
        </body>
      </body>
      <body name="shoulder_2" pos="-1.06038e-05 0.0180896 -0.1875" quat="2.32051e-08 0 0 -1">
        <inertial pos="-0.00808783 -0.00106204 -0.0669464" quat="0.997954 0.0243151 0.0359066 -0.0469722" mass="0.984978" diaginertia="0.00148321 0.00121718 0.00114258" />
        <joint name="R_shoulder_y" pos="0 0 0" axis="0 0 1" range="-3.14159 0" actuatorfrcrange="-80 80" />
        <geom type="mesh" rgba="0.121569 0.121569 0.137255 1" mesh="shoulder_2" contype="1" conaffinity="0" density="0" group="1" class="visualgeom" />
        <geom type="mesh" rgba="0.121569 0.121569 0.137255 1" mesh="shoulder_2" />
        <body name="arm1_top_2" pos="0.022512 -5.62784e-05 -0.0675" quat="0.5 0.5 -0.5 -0.5">
          <inertial pos="-0.0793712 -0.00125008 0.0133662" quat="0.0371983 0.820683 0.0499765 0.567978" mass="1.10471" diaginertia="0.00408867 0.00384907 0.00107265" />
          <joint name="R_shoulder_x" pos="0 0 0" axis="0 0 1" range="-0.479966 3.63028" actuatorfrcrange="-80 80" />
          <geom type="mesh" rgba="0.121569 0.121569 0.137255 1" mesh="arm1_top_2" contype="1" conaffinity="0" density="0" group="1" class="visualgeom" />
          <geom type="mesh" rgba="0.121569 0.121569 0.137255 1" mesh="arm1_top_2" />
          <body name="arm2_shell_2" pos="-0.1395 0 0.0225" quat="1.64085e-08 -0.707107 1.64085e-08 0.707107">
            <inertial pos="0.00179871 0.00117563 0.0689628" quat="0.999115 0.0291134 0.0300502 0.00441807" mass="0.888739" diaginertia="0.00186471 0.0017354 0.000866031" />
            <joint name="R_shoulder_z" pos="0 0 0" axis="0 0 -1" range="-1.5708 1.5708" actuatorfrcrange="-80 80" />
            <geom type="mesh" rgba="0.121569 0.121569 0.137255 1" mesh="arm2_shell_2" contype="1" conaffinity="0" density="0" group="1" class="visualgeom" />
            <geom type="mesh" rgba="0.121569 0.121569 0.137255 1" mesh="arm2_shell_2" />
            <body name="arm3_shell2" pos="0.026 0 0.0975" quat="1.64085e-08 -0.707107 1.64085e-08 0.707107">
              <inertial pos="-0.111658 -1.90252e-06 0.0179545" quat="0.000339011 0.750827 0.00037652 0.660498" mass="1.17435" diaginertia="0.0039329 0.00386555 0.0012513" />
              <joint name="R_elbow" pos="0 0 0" axis="0 0 1" range="0 2.53073" actuatorfrcrange="-80 80" />
              <geom type="mesh" rgba="0.121569 0.121569 0.137255 1" mesh="arm3_shell2" contype="1" conaffinity="0" density="0" group="1" class="visualgeom" />
              <geom type="mesh" rgba="0.121569 0.121569 0.137255 1" mesh="arm3_shell2" />
              <body name="hand_shell_2" pos="-0.1815 -1.46192e-09 0.0215" quat="0.5 -0.5 0.5 -0.5">
                <inertial pos="0.000708717 0.00012971 -0.0746297" quat="0.70677 0.0116364 0.0100591 0.707276" mass="0.793352" diaginertia="0.00287111 0.002036 0.00127892" />
                <joint name="L_wrist" pos="0 0 0" axis="0 0 1" range="0 6.28319" actuatorfrcrange="-80 80" />
                <geom type="mesh" rgba="0.121569 0.121569 0.137255 1" mesh="hand_shell_2" contype="1" conaffinity="0" density="0" group="1" class="visualgeom" />
                <geom type="mesh" rgba="0.121569 0.121569 0.137255 1" mesh="hand_shell_2" />
              </body>
            </body>
          </body>
        </body>
      </body>
      <body name="leg0_shell" pos="-1.06085e-05 -0.43201 0.0877" quat="2.32051e-08 0 1 -7.32051e-08">
        <inertial pos="-0.00374632 -5.30704e-10 -0.0681251" quat="0.999982 0 -0.00597565 0" mass="1.32345" diaginertia="0.0018859 0.00142483 0.00129962" />
        <joint name="L_hip_y" pos="0 0 0" axis="0 0 1" range="-1.5708 1.5708" actuatorfrcrange="-80 80" />
        <geom type="mesh" rgba="0.121569 0.121569 0.137255 1" mesh="leg0_shell" contype="1" conaffinity="0" density="0" group="1" class="visualgeom" />
        <geom type="mesh" rgba="0.121569 0.121569 0.137255 1" mesh="leg0_shell" />
        <body name="leg1_shell" pos="0.0265 -1.51659e-09 -0.0695" quat="0.5 -0.5 -0.5 0.5">
          <inertial pos="-0.095008 0.0037889 0.0261069" quat="0.491547 0.526837 0.511484 0.468197" mass="2.39754" diaginertia="0.00948319 0.0088461 0.00510047" />
          <joint name="L_hip_x" pos="0 0 0" axis="0 0 1" range="-0.349066 3.18523" actuatorfrcrange="-80 80" />
          <geom type="mesh" rgba="0.121569 0.121569 0.137255 1" mesh="leg1_shell" contype="1" conaffinity="0" density="0" group="1" class="visualgeom" />
          <geom type="mesh" rgba="0.121569 0.121569 0.137255 1" mesh="leg1_shell" />
          <body name="leg2_shell" pos="-0.1565 0.000119814 0.0275" quat="0.707107 0 0.707107 0">
            <inertial pos="0.00146207 9.40256e-06 -0.114948" quat="0.714871 0.0282367 0.0196615 0.698409" mass="2.36731" diaginertia="0.00939993 0.00817177 0.00374967" />
            <joint name="L_hip_z" pos="0 0 0" axis="0 0 1" range="-1.5708 1.5708" actuatorfrcrange="-80 80" />
            <geom type="mesh" rgba="0.121569 0.121569 0.137255 1" mesh="leg2_shell" contype="1" conaffinity="0" density="0" group="1" class="visualgeom" />
            <geom type="mesh" rgba="0.121569 0.121569 0.137255 1" mesh="leg2_shell" />
            <body name="leg3_shell2" pos="0 0.0342 -0.1425" quat="0.707107 0.707107 0 0">
              <inertial pos="0.000692643 -0.0906724 0.0320265" quat="0.722394 0.691168 0.0174263 -0.0113733" mass="1.75933" diaginertia="0.0146368 0.0141424 0.00277765" />
              <joint name="L_knee" pos="0 0 0" axis="0 0 1" range="-2.0944 2.0944" actuatorfrcrange="-80 80" />
              <geom type="mesh" rgba="0.121569 0.121569 0.137255 1" mesh="leg3_shell2" contype="1" conaffinity="0" density="0" group="1" class="visualgeom" />
              <geom type="mesh" rgba="0.121569 0.121569 0.137255 1" mesh="leg3_shell2" />
              <body name="foot1" pos="0 -0.3 0.0702" quat="1 4.64102e-08 0 0">
                <inertial pos="0.0210264 -0.018472 -0.0193043" quat="0.505269 0.504957 0.48518 0.504304" mass="0.545747" diaginertia="0.00202977 0.00187214 0.000259286" />
                <joint name="L_ankle" pos="0 0 0" axis="0 0 -1" range="-0.698132 0.698132" actuatorfrcrange="-80 80" />
                <geom type="mesh" rgba="0.121569 0.121569 0.137255 1" mesh="foot1" contype="1" conaffinity="0" density="0" group="1" class="visualgeom" />
                <geom type="mesh" rgba="0.121569 0.121569 0.137255 1" mesh="foot1" />
              </body>
            </body>
          </body>
        </body>
      </body>
      <body name="leg0_shell_2" pos="-1.06003e-05 -0.43201 -0.0882" quat="0 2.32051e-08 -5e-08 -1">
        <inertial pos="-0.00374632 -5.30704e-10 -0.0681251" quat="0.999982 0 -0.00597565 0" mass="1.32345" diaginertia="0.0018859 0.00142483 0.00129962" />
        <joint name="R_hip_y" pos="0 0 0" axis="0 0 1" range="-1.5708 1.5708" actuatorfrcrange="-80 80" />
        <geom type="mesh" rgba="0.121569 0.121569 0.137255 1" mesh="leg0_shell_2" contype="1" conaffinity="0" density="0" group="1" class="visualgeom" />
        <geom type="mesh" rgba="0.121569 0.121569 0.137255 1" mesh="leg0_shell_2" />
        <body name="leg1_shell3" pos="0.0265 -1.51659e-09 -0.0695" quat="0.5 0.5 -0.5 -0.5">
          <inertial pos="-0.0949078 -0.0037889 0.0261069" quat="0.468237 0.512268 0.526385 0.491177" mass="2.39754" diaginertia="0.00944772 0.00881137 0.00510089" />
          <joint name="R_hip_x" pos="0 0 0" axis="0 0 1" range="-0.349066 3.18523" actuatorfrcrange="-80 80" />
          <geom type="mesh" rgba="0.121569 0.121569 0.137255 1" mesh="leg1_shell3" contype="1" conaffinity="0" density="0" group="1" class="visualgeom" />
          <geom type="mesh" rgba="0.121569 0.121569 0.137255 1" mesh="leg1_shell3" />
          <body name="leg2_shell_2" pos="-0.1565 -0.000119814 0.0275" quat="0 -0.707107 0 -0.707107">
            <inertial pos="-0.00146137 9.41194e-06 -0.114948" quat="0.698405 -0.0196604 -0.0282353 0.714875" mass="2.3673" diaginertia="0.00939994 0.00817176 0.00374968" />
            <joint name="R_hip_z" pos="0 0 0" axis="0 0 1" range="-1.5708 1.5708" actuatorfrcrange="-80 80" />
            <geom type="mesh" rgba="0.121569 0.121569 0.137255 1" mesh="leg2_shell_2" contype="1" conaffinity="0" density="0" group="1" class="visualgeom" />
            <geom type="mesh" rgba="0.121569 0.121569 0.137255 1" mesh="leg2_shell_2" />
            <body name="leg3_shell22" pos="0 0.0342 -0.1425" quat="0.707107 0.707107 0 0">
              <inertial pos="-0.000692674 -0.0906727 0.0320266" quat="0.722394 0.691168 -0.0174271 0.0113737" mass="1.75934" diaginertia="0.0146369 0.0141424 0.00277766" />
              <joint name="R_knee" pos="0 0 0" axis="0 0 -1" range="-2.0944 2.0944" actuatorfrcrange="-80 80" />
              <geom type="mesh" rgba="0.121569 0.121569 0.137255 1" mesh="leg3_shell22" contype="1" conaffinity="0" density="0" group="1" class="visualgeom" />
              <geom type="mesh" rgba="0.121569 0.121569 0.137255 1" mesh="leg3_shell22" />
              <body name="foot3" pos="1.07672e-08 -0.3 0.0272" quat="0 -2.32051e-08 1 -2.32051e-08">
                <inertial pos="0.0210264 -0.018472 -0.0236957" quat="0.504957 0.505269 0.504304 0.48518" mass="0.545747" diaginertia="0.00202977 0.00187214 0.000259286" />
                <joint name="R_ankle" pos="0 0 0" axis="0 0 -1" range="-0.698132 0.698132" actuatorfrcrange="-80 80" />
                <geom type="mesh" rgba="0.121569 0.121569 0.137255 1" mesh="foot3" contype="1" conaffinity="0" density="0" group="1" class="visualgeom" />
                <geom type="mesh" rgba="0.121569 0.121569 0.137255 1" mesh="foot3" />
              </body>
            </body>
          </body>
        </body>
      </body>
    </body>
  </worldbody>

  <actuator>
    <motor name="L_shoulder_y" joint="L_shoulder_y" ctrllimited="true" ctrlrange="-80 80" gear="1" />
    <motor name="L_shoulder_x" joint="L_shoulder_x" ctrllimited="true" ctrlrange="-80 80" gear="1" />
    <motor name="L_shoulder_z" joint="L_shoulder_z" ctrllimited="true" ctrlrange="-80 80" gear="1" />
    <motor name="L_elbow" joint="L_elbow" ctrllimited="true" ctrlrange="-80 80" gear="1" />
    <motor name="R_wrist" joint="R_wrist" ctrllimited="true" ctrlrange="-80 80" gear="1" />
    <motor name="R_shoulder_y" joint="R_shoulder_y" ctrllimited="true" ctrlrange="-80 80" gear="1" />
    <motor name="R_shoulder_x" joint="R_shoulder_x" ctrllimited="true" ctrlrange="-80 80" gear="1" />
    <motor name="R_shoulder_z" joint="R_shoulder_z" ctrllimited="true" ctrlrange="-80 80" gear="1" />
    <motor name="R_elbow" joint="R_elbow" ctrllimited="true" ctrlrange="-80 80" gear="1" />
    <motor name="L_wrist" joint="L_wrist" ctrllimited="true" ctrlrange="-80 80" gear="1" />
    <motor name="L_hip_y" joint="L_hip_y" ctrllimited="true" ctrlrange="-80 80" gear="1" />
    <motor name="L_hip_x" joint="L_hip_x" ctrllimited="true" ctrlrange="-80 80" gear="1" />
    <motor name="L_hip_z" joint="L_hip_z" ctrllimited="true" ctrlrange="-80 80" gear="1" />
    <motor name="L_knee" joint="L_knee" ctrllimited="true" ctrlrange="-80 80" gear="1" />
    <motor name="L_ankle" joint="L_ankle" ctrllimited="true" ctrlrange="-80 80" gear="1" />
    <motor name="R_hip_y" joint="R_hip_y" ctrllimited="true" ctrlrange="-80 80" gear="1" />
    <motor name="R_hip_x" joint="R_hip_x" ctrllimited="true" ctrlrange="-80 80" gear="1" />
    <motor name="R_hip_z" joint="R_hip_z" ctrllimited="true" ctrlrange="-80 80" gear="1" />
    <motor name="R_knee" joint="R_knee" ctrllimited="true" ctrlrange="-80 80" gear="1" />
    <motor name="R_ankle" joint="R_ankle" ctrllimited="true" ctrlrange="-80 80" gear="1" />
  </actuator>

  <sensor>
    <actuatorpos name="L_shoulder_y_p" actuator="L_shoulder_y" />
    <actuatorvel name="L_shoulder_y_v" actuator="L_shoulder_y" />
    <actuatorfrc name="L_shoulder_y_f" actuator="L_shoulder_y" noise="0.001" />
    <actuatorpos name="L_shoulder_x_p" actuator="L_shoulder_x" />
    <actuatorvel name="L_shoulder_x_v" actuator="L_shoulder_x" />
    <actuatorfrc name="L_shoulder_x_f" actuator="L_shoulder_x" noise="0.001" />
    <actuatorpos name="L_shoulder_z_p" actuator="L_shoulder_z" />
    <actuatorvel name="L_shoulder_z_v" actuator="L_shoulder_z" />
    <actuatorfrc name="L_shoulder_z_f" actuator="L_shoulder_z" noise="0.001" />
    <actuatorpos name="L_elbow_p" actuator="L_elbow" />
    <actuatorvel name="L_elbow_v" actuator="L_elbow" />
    <actuatorfrc name="L_elbow_f" actuator="L_elbow" noise="0.001" />
    <actuatorpos name="R_wrist_p" actuator="R_wrist" />
    <actuatorvel name="R_wrist_v" actuator="R_wrist" />
    <actuatorfrc name="R_wrist_f" actuator="R_wrist" noise="0.001" />
    <actuatorpos name="R_shoulder_y_p" actuator="R_shoulder_y" />
    <actuatorvel name="R_shoulder_y_v" actuator="R_shoulder_y" />
    <actuatorfrc name="R_shoulder_y_f" actuator="R_shoulder_y" noise="0.001" />
    <actuatorpos name="R_shoulder_x_p" actuator="R_shoulder_x" />
    <actuatorvel name="R_shoulder_x_v" actuator="R_shoulder_x" />
    <actuatorfrc name="R_shoulder_x_f" actuator="R_shoulder_x" noise="0.001" />
    <actuatorpos name="R_shoulder_z_p" actuator="R_shoulder_z" />
    <actuatorvel name="R_shoulder_z_v" actuator="R_shoulder_z" />
    <actuatorfrc name="R_shoulder_z_f" actuator="R_shoulder_z" noise="0.001" />
    <actuatorpos name="R_elbow_p" actuator="R_elbow" />
    <actuatorvel name="R_elbow_v" actuator="R_elbow" />
    <actuatorfrc name="R_elbow_f" actuator="R_elbow" noise="0.001" />
    <actuatorpos name="L_wrist_p" actuator="L_wrist" />
    <actuatorvel name="L_wrist_v" actuator="L_wrist" />
    <actuatorfrc name="L_wrist_f" actuator="L_wrist" noise="0.001" />
    <actuatorpos name="L_hip_y_p" actuator="L_hip_y" />
    <actuatorvel name="L_hip_y_v" actuator="L_hip_y" />
    <actuatorfrc name="L_hip_y_f" actuator="L_hip_y" noise="0.001" />
    <actuatorpos name="L_hip_x_p" actuator="L_hip_x" />
    <actuatorvel name="L_hip_x_v" actuator="L_hip_x" />
    <actuatorfrc name="L_hip_x_f" actuator="L_hip_x" noise="0.001" />
    <actuatorpos name="L_hip_z_p" actuator="L_hip_z" />
    <actuatorvel name="L_hip_z_v" actuator="L_hip_z" />
    <actuatorfrc name="L_hip_z_f" actuator="L_hip_z" noise="0.001" />
    <actuatorpos name="L_knee_p" actuator="L_knee" />
    <actuatorvel name="L_knee_v" actuator="L_knee" />
    <actuatorfrc name="L_knee_f" actuator="L_knee" noise="0.001" />
    <actuatorpos name="L_ankle_p" actuator="L_ankle" />
    <actuatorvel name="L_ankle_v" actuator="L_ankle" />
    <actuatorfrc name="L_ankle_f" actuator="L_ankle" noise="0.001" />
    <actuatorpos name="R_hip_y_p" actuator="R_hip_y" />
    <actuatorvel name="R_hip_y_v" actuator="R_hip_y" />
    <actuatorfrc name="R_hip_y_f" actuator="R_hip_y" noise="0.001" />
    <actuatorpos name="R_hip_x_p" actuator="R_hip_x" />
    <actuatorvel name="R_hip_x_v" actuator="R_hip_x" />
    <actuatorfrc name="R_hip_x_f" actuator="R_hip_x" noise="0.001" />
    <actuatorpos name="R_hip_z_p" actuator="R_hip_z" />
    <actuatorvel name="R_hip_z_v" actuator="R_hip_z" />
    <actuatorfrc name="R_hip_z_f" actuator="R_hip_z" noise="0.001" />
    <actuatorpos name="R_knee_p" actuator="R_knee" />
    <actuatorvel name="R_knee_v" actuator="R_knee" />
    <actuatorfrc name="R_knee_f" actuator="R_knee" noise="0.001" />
    <actuatorpos name="R_ankle_p" actuator="R_ankle" />
    <actuatorvel name="R_ankle_v" actuator="R_ankle" />
    <actuatorfrc name="R_ankle_f" actuator="R_ankle" noise="0.001" />
    <framequat name="orientation" objtype="site" noise="0.001" objname="imu" />
    <gyro name="angular-velocity" site="imu" noise="0.005" cutoff="34.9" />
  </sensor>
</mujoco>